<?xml version="1.0" ?>
<!-- =================================================================================== -->
<!-- |    This document was autogenerated by xacro from grip.xacro                     | -->
<!-- |    EDITING THIS FILE BY HAND IS NOT RECOMMENDED                                 | -->
<!-- =================================================================================== -->
<robot name="test_bot" xmlns:xacro="http://www.ros.org/wiki/xacro">
  <link name="base_link">
    <visual>
      <geometry>
        <cylinder length="0.02" radius="1"/>
      </geometry>
      <origin rpy="0 0 0"/>
      <material name="red">
        <color rgba="1 0 0 1"/>
      </material>
    </visual>
  </link>
  <link name="master_bot_straw">
    <visual>
      <geometry>
        <cylinder length="0.3" radius="0.02"/>
      </geometry>
      <origin rpy="0 0 0" xyz="0 0 0.15"/>
      <material name="green">
        <color rgba="0 1 0 1"/>
      </material>
    </visual>
  </link>
  <link name="master_top_straw">
    <visual>
      <geometry>
        <cylinder length="0.3" radius="0.02"/>
      </geometry>
      <origin rpy="0 0 0" xyz="0 0 0.15"/>
      <material name="green">
        <color rgba="0 1 0 1"/>
      </material>
    </visual>
  </link>
  <joint name="master_main_joint" type="revolute">
    <parent link="base_link"/>
    <child link="master_bot_straw"/>
    <origin xyz="0.1 0.0 0"/>
    <axis xyz="0.0 -0.1 0"/>
    <limit effort="300" lower="-1.5707963268" upper="0" velocity="0.1"/>
    <dynamics damping="50" friction="1"/>
  </joint>
  <joint name="master_slave_joint" type="revolute">
    <parent link="master_bot_straw"/>
    <child link="master_top_straw"/>
    <origin xyz="0 0 0.3"/>
    <axis xyz="0.0 -0.1 0"/>
    <limit effort="300" lower="-3.14159265359" upper="3.14159265359" velocity="0.1"/>
    <mimic joint="master_main_joint" multiplier="-2.0" offset="0.0"/>
    <dynamics damping="50" friction="1"/>
  </joint>
  <link name="no1_bot_straw">
    <visual>
      <geometry>
        <cylinder length="0.3" radius="0.02"/>
      </geometry>
      <origin rpy="0 0 0" xyz="0 0 0.15"/>
      <material name="green">
        <color rgba="0 1 0 1"/>
      </material>
    </visual>
  </link>
  <link name="no1_top_straw">
    <visual>
      <geometry>
        <cylinder length="0.3" radius="0.02"/>
      </geometry>
      <origin rpy="0 0 0" xyz="0 0 0.15"/>
      <material name="green">
        <color rgba="0 1 0 1"/>
      </material>
    </visual>
  </link>
  <joint name="no1_main_joint" type="revolute">
    <parent link="base_link"/>
    <child link="no1_bot_straw"/>
    <origin xyz="0.0998026728428 0.00627905195293 0"/>
    <axis xyz="0.00627905195293 -0.0998026728428 0"/>
    <limit effort="300" lower="-1.5707963268" upper="0" velocity="0.1"/>
    <mimic joint="master_main_joint" multiplier="1.0" offset="0.0"/>
    <dynamics damping="50" friction="1"/>
  </joint>
  <joint name="no1_slave_joint" type="revolute">
    <parent link="no1_bot_straw"/>
    <child link="no1_top_straw"/>
    <origin xyz="0 0 0.3"/>
    <axis xyz="0.00627905195293 -0.0998026728428 0"/>
    <limit effort="300" lower="-3.14159265359" upper="3.14159265359" velocity="0.1"/>
    <mimic joint="no1_main_joint" multiplier="-2.0" offset="0.0"/>
    <dynamics damping="50" friction="1"/>
  </joint>
  <link name="no2_bot_straw">
    <visual>
      <geometry>
        <cylinder length="0.3" radius="0.02"/>
      </geometry>
      <origin rpy="0 0 0" xyz="0 0 0.15"/>
      <material name="green">
        <color rgba="0 1 0 1"/>
      </material>
    </visual>
  </link>
  <link name="no2_top_straw">
    <visual>
      <geometry>
        <cylinder length="0.3" radius="0.02"/>
      </geometry>
      <origin rpy="0 0 0" xyz="0 0 0.15"/>
      <material name="green">
        <color rgba="0 1 0 1"/>
      </material>
    </visual>
  </link>
  <joint name="no2_main_joint" type="revolute">
    <parent link="base_link"/>
    <child link="no2_bot_straw"/>
    <origin xyz="0.0992114701314 0.0125333233564 0"/>
    <axis xyz="0.0125333233564 -0.0992114701314 0"/>
    <limit effort="300" lower="-1.5707963268" upper="0" velocity="0.1"/>
    <mimic joint="master_main_joint" multiplier="1.0" offset="0.0"/>
    <dynamics damping="50" friction="1"/>
  </joint>
  <joint name="no2_slave_joint" type="revolute">
    <parent link="no2_bot_straw"/>
    <child link="no2_top_straw"/>
    <origin xyz="0 0 0.3"/>
    <axis xyz="0.0125333233564 -0.0992114701314 0"/>
    <limit effort="300" lower="-3.14159265359" upper="3.14159265359" velocity="0.1"/>
    <mimic joint="no2_main_joint" multiplier="-2.0" offset="0.0"/>
    <dynamics damping="50" friction="1"/>
  </joint>
  <link name="no3_bot_straw">
    <visual>
      <geometry>
        <cylinder length="0.3" radius="0.02"/>
      </geometry>
      <origin rpy="0 0 0" xyz="0 0 0.15"/>
      <material name="green">
        <color rgba="0 1 0 1"/>
      </material>
    </visual>
  </link>
  <link name="no3_top_straw">
    <visual>
      <geometry>
        <cylinder length="0.3" radius="0.02"/>
      </geometry>
      <origin rpy="0 0 0" xyz="0 0 0.15"/>
      <material name="green">
        <color rgba="0 1 0 1"/>
      </material>
    </visual>
  </link>
  <joint name="no3_main_joint" type="revolute">
    <parent link="base_link"/>
    <child link="no3_bot_straw"/>
    <origin xyz="0.0982287250729 0.0187381314586 0"/>
    <axis xyz="0.0187381314586 -0.0982287250729 0"/>
    <limit effort="300" lower="-1.5707963268" upper="0" velocity="0.1"/>
    <mimic joint="master_main_joint" multiplier="1.0" offset="0.0"/>
    <dynamics damping="50" friction="1"/>
  </joint>
  <joint name="no3_slave_joint" type="revolute">
    <parent link="no3_bot_straw"/>
    <child link="no3_top_straw"/>
    <origin xyz="0 0 0.3"/>
    <axis xyz="0.0187381314586 -0.0982287250729 0"/>
    <limit effort="300" lower="-3.14159265359" upper="3.14159265359" velocity="0.1"/>
    <mimic joint="no3_main_joint" multiplier="-2.0" offset="0.0"/>
    <dynamics damping="50" friction="1"/>
  </joint>
  <link name="no4_bot_straw">
    <visual>
      <geometry>
        <cylinder length="0.3" radius="0.02"/>
      </geometry>
      <origin rpy="0 0 0" xyz="0 0 0.15"/>
      <material name="green">
        <color rgba="0 1 0 1"/>
      </material>
    </visual>
  </link>
  <link name="no4_top_straw">
    <visual>
      <geometry>
        <cylinder length="0.3" radius="0.02"/>
      </geometry>
      <origin rpy="0 0 0" xyz="0 0 0.15"/>
      <material name="green">
        <color rgba="0 1 0 1"/>
      </material>
    </visual>
  </link>
  <joint name="no4_main_joint" type="revolute">
    <parent link="base_link"/>
    <child link="no4_bot_straw"/>
    <origin xyz="0.0968583161129 0.0248689887165 0"/>
    <axis xyz="0.0248689887165 -0.0968583161129 0"/>
    <limit effort="300" lower="-1.5707963268" upper="0" velocity="0.1"/>
    <mimic joint="master_main_joint" multiplier="1.0" offset="0.0"/>
    <dynamics damping="50" friction="1"/>
  </joint>
  <joint name="no4_slave_joint" type="revolute">
    <parent link="no4_bot_straw"/>
    <child link="no4_top_straw"/>
    <origin xyz="0 0 0.3"/>
    <axis xyz="0.0248689887165 -0.0968583161129 0"/>
    <limit effort="300" lower="-3.14159265359" upper="3.14159265359" velocity="0.1"/>
    <mimic joint="no4_main_joint" multiplier="-2.0" offset="0.0"/>
    <dynamics damping="50" friction="1"/>
  </joint>
  <link name="no5_bot_straw">
    <visual>
      <geometry>
        <cylinder length="0.3" radius="0.02"/>
      </geometry>
      <origin rpy="0 0 0" xyz="0 0 0.15"/>
      <material name="green">
        <color rgba="0 1 0 1"/>
      </material>
    </visual>
  </link>
  <link name="no5_top_straw">
    <visual>
      <geometry>
        <cylinder length="0.3" radius="0.02"/>
      </geometry>
      <origin rpy="0 0 0" xyz="0 0 0.15"/>
      <material name="green">
        <color rgba="0 1 0 1"/>
      </material>
    </visual>
  </link>
  <joint name="no5_main_joint" type="revolute">
    <parent link="base_link"/>
    <child link="no5_bot_straw"/>
    <origin xyz="0.0951056516295 0.0309016994375 0"/>
    <axis xyz="0.0309016994375 -0.0951056516295 0"/>
    <limit effort="300" lower="-1.5707963268" upper="0" velocity="0.1"/>
    <mimic joint="master_main_joint" multiplier="1.0" offset="0.0"/>
    <dynamics damping="50" friction="1"/>
  </joint>
  <joint name="no5_slave_joint" type="revolute">
    <parent link="no5_bot_straw"/>
    <child link="no5_top_straw"/>
    <origin xyz="0 0 0.3"/>
    <axis xyz="0.0309016994375 -0.0951056516295 0"/>
    <limit effort="300" lower="-3.14159265359" upper="3.14159265359" velocity="0.1"/>
    <mimic joint="no5_main_joint" multiplier="-2.0" offset="0.0"/>
    <dynamics damping="50" friction="1"/>
  </joint>
  <link name="no6_bot_straw">
    <visual>
      <geometry>
        <cylinder length="0.3" radius="0.02"/>
      </geometry>
      <origin rpy="0 0 0" xyz="0 0 0.15"/>
      <material name="green">
        <color rgba="0 1 0 1"/>
      </material>
    </visual>
  </link>
  <link name="no6_top_straw">
    <visual>
      <geometry>
        <cylinder length="0.3" radius="0.02"/>
      </geometry>
      <origin rpy="0 0 0" xyz="0 0 0.15"/>
      <material name="green">
        <color rgba="0 1 0 1"/>
      </material>
    </visual>
  </link>
  <joint name="no6_main_joint" type="revolute">
    <parent link="base_link"/>
    <child link="no6_bot_straw"/>
    <origin xyz="0.0929776485888 0.0368124552685 0"/>
    <axis xyz="0.0368124552685 -0.0929776485888 0"/>
    <limit effort="300" lower="-1.5707963268" upper="0" velocity="0.1"/>
    <mimic joint="master_main_joint" multiplier="1.0" offset="0.0"/>
    <dynamics damping="50" friction="1"/>
  </joint>
  <joint name="no6_slave_joint" type="revolute">
    <parent link="no6_bot_straw"/>
    <child link="no6_top_straw"/>
    <origin xyz="0 0 0.3"/>
    <axis xyz="0.0368124552685 -0.0929776485888 0"/>
    <limit effort="300" lower="-3.14159265359" upper="3.14159265359" velocity="0.1"/>
    <mimic joint="no6_main_joint" multiplier="-2.0" offset="0.0"/>
    <dynamics damping="50" friction="1"/>
  </joint>
  <link name="no7_bot_straw">
    <visual>
      <geometry>
        <cylinder length="0.3" radius="0.02"/>
      </geometry>
      <origin rpy="0 0 0" xyz="0 0 0.15"/>
      <material name="green">
        <color rgba="0 1 0 1"/>
      </material>
    </visual>
  </link>
  <link name="no7_top_straw">
    <visual>
      <geometry>
        <cylinder length="0.3" radius="0.02"/>
      </geometry>
      <origin rpy="0 0 0" xyz="0 0 0.15"/>
      <material name="green">
        <color rgba="0 1 0 1"/>
      </material>
    </visual>
  </link>
  <joint name="no7_main_joint" type="revolute">
    <parent link="base_link"/>
    <child link="no7_bot_straw"/>
    <origin xyz="0.0904827052466 0.0425779291565 0"/>
    <axis xyz="0.0425779291565 -0.0904827052466 0"/>
    <limit effort="300" lower="-1.5707963268" upper="0" velocity="0.1"/>
    <mimic joint="master_main_joint" multiplier="1.0" offset="0.0"/>
    <dynamics damping="50" friction="1"/>
  </joint>
  <joint name="no7_slave_joint" type="revolute">
    <parent link="no7_bot_straw"/>
    <child link="no7_top_straw"/>
    <origin xyz="0 0 0.3"/>
    <axis xyz="0.0425779291565 -0.0904827052466 0"/>
    <limit effort="300" lower="-3.14159265359" upper="3.14159265359" velocity="0.1"/>
    <mimic joint="no7_main_joint" multiplier="-2.0" offset="0.0"/>
    <dynamics damping="50" friction="1"/>
  </joint>
  <link name="no8_bot_straw">
    <visual>
      <geometry>
        <cylinder length="0.3" radius="0.02"/>
      </geometry>
      <origin rpy="0 0 0" xyz="0 0 0.15"/>
      <material name="green">
        <color rgba="0 1 0 1"/>
      </material>
    </visual>
  </link>
  <link name="no8_top_straw">
    <visual>
      <geometry>
        <cylinder length="0.3" radius="0.02"/>
      </geometry>
      <origin rpy="0 0 0" xyz="0 0 0.15"/>
      <material name="green">
        <color rgba="0 1 0 1"/>
      </material>
    </visual>
  </link>
  <joint name="no8_main_joint" type="revolute">
    <parent link="base_link"/>
    <child link="no8_bot_straw"/>
    <origin xyz="0.0876306680044 0.0481753674102 0"/>
    <axis xyz="0.0481753674102 -0.0876306680044 0"/>
    <limit effort="300" lower="-1.5707963268" upper="0" velocity="0.1"/>
    <mimic joint="master_main_joint" multiplier="1.0" offset="0.0"/>
    <dynamics damping="50" friction="1"/>
  </joint>
  <joint name="no8_slave_joint" type="revolute">
    <parent link="no8_bot_straw"/>
    <child link="no8_top_straw"/>
    <origin xyz="0 0 0.3"/>
    <axis xyz="0.0481753674102 -0.0876306680044 0"/>
    <limit effort="300" lower="-3.14159265359" upper="3.14159265359" velocity="0.1"/>
    <mimic joint="no8_main_joint" multiplier="-2.0" offset="0.0"/>
    <dynamics damping="50" friction="1"/>
  </joint>
  <link name="no9_bot_straw">
    <visual>
      <geometry>
        <cylinder length="0.3" radius="0.02"/>
      </geometry>
      <origin rpy="0 0 0" xyz="0 0 0.15"/>
      <material name="green">
        <color rgba="0 1 0 1"/>
      </material>
    </visual>
  </link>
  <link name="no9_top_straw">
    <visual>
      <geometry>
        <cylinder length="0.3" radius="0.02"/>
      </geometry>
      <origin rpy="0 0 0" xyz="0 0 0.15"/>
      <material name="green">
        <color rgba="0 1 0 1"/>
      </material>
    </visual>
  </link>
  <joint name="no9_main_joint" type="revolute">
    <parent link="base_link"/>
    <child link="no9_bot_straw"/>
    <origin xyz="0.0844327925502 0.0535826794979 0"/>
    <axis xyz="0.0535826794979 -0.0844327925502 0"/>
    <limit effort="300" lower="-1.5707963268" upper="0" velocity="0.1"/>
    <mimic joint="master_main_joint" multiplier="1.0" offset="0.0"/>
    <dynamics damping="50" friction="1"/>
  </joint>
  <joint name="no9_slave_joint" type="revolute">
    <parent link="no9_bot_straw"/>
    <child link="no9_top_straw"/>
    <origin xyz="0 0 0.3"/>
    <axis xyz="0.0535826794979 -0.0844327925502 0"/>
    <limit effort="300" lower="-3.14159265359" upper="3.14159265359" velocity="0.1"/>
    <mimic joint="no9_main_joint" multiplier="-2.0" offset="0.0"/>
    <dynamics damping="50" friction="1"/>
  </joint>
  <link name="no10_bot_straw">
    <visual>
      <geometry>
        <cylinder length="0.3" radius="0.02"/>
      </geometry>
      <origin rpy="0 0 0" xyz="0 0 0.15"/>
      <material name="green">
        <color rgba="0 1 0 1"/>
      </material>
    </visual>
  </link>
  <link name="no10_top_straw">
    <visual>
      <geometry>
        <cylinder length="0.3" radius="0.02"/>
      </geometry>
      <origin rpy="0 0 0" xyz="0 0 0.15"/>
      <material name="green">
        <color rgba="0 1 0 1"/>
      </material>
    </visual>
  </link>
  <joint name="no10_main_joint" type="revolute">
    <parent link="base_link"/>
    <child link="no10_bot_straw"/>
    <origin xyz="0.0809016994375 0.0587785252293 0"/>
    <axis xyz="0.0587785252293 -0.0809016994375 0"/>
    <limit effort="300" lower="-1.5707963268" upper="0" velocity="0.1"/>
    <mimic joint="master_main_joint" multiplier="1.0" offset="0.0"/>
    <dynamics damping="50" friction="1"/>
  </joint>
  <joint name="no10_slave_joint" type="revolute">
    <parent link="no10_bot_straw"/>
    <child link="no10_top_straw"/>
    <origin xyz="0 0 0.3"/>
    <axis xyz="0.0587785252293 -0.0809016994375 0"/>
    <limit effort="300" lower="-3.14159265359" upper="3.14159265359" velocity="0.1"/>
    <mimic joint="no10_main_joint" multiplier="-2.0" offset="0.0"/>
    <dynamics damping="50" friction="1"/>
  </joint>
  <link name="no11_bot_straw">
    <visual>
      <geometry>
        <cylinder length="0.3" radius="0.02"/>
      </geometry>
      <origin rpy="0 0 0" xyz="0 0 0.15"/>
      <material name="green">
        <color rgba="0 1 0 1"/>
      </material>
    </visual>
  </link>
  <link name="no11_top_straw">
    <visual>
      <geometry>
        <cylinder length="0.3" radius="0.02"/>
      </geometry>
      <origin rpy="0 0 0" xyz="0 0 0.15"/>
      <material name="green">
        <color rgba="0 1 0 1"/>
      </material>
    </visual>
  </link>
  <joint name="no11_main_joint" type="revolute">
    <parent link="base_link"/>
    <child link="no11_bot_straw"/>
    <origin xyz="0.0770513242776 0.0637423989749 0"/>
    <axis xyz="0.0637423989749 -0.0770513242776 0"/>
    <limit effort="300" lower="-1.5707963268" upper="0" velocity="0.1"/>
    <mimic joint="master_main_joint" multiplier="1.0" offset="0.0"/>
    <dynamics damping="50" friction="1"/>
  </joint>
  <joint name="no11_slave_joint" type="revolute">
    <parent link="no11_bot_straw"/>
    <child link="no11_top_straw"/>
    <origin xyz="0 0 0.3"/>
    <axis xyz="0.0637423989749 -0.0770513242776 0"/>
    <limit effort="300" lower="-3.14159265359" upper="3.14159265359" velocity="0.1"/>
    <mimic joint="no11_main_joint" multiplier="-2.0" offset="0.0"/>
    <dynamics damping="50" friction="1"/>
  </joint>
  <link name="no12_bot_straw">
    <visual>
      <geometry>
        <cylinder length="0.3" radius="0.02"/>
      </geometry>
      <origin rpy="0 0 0" xyz="0 0 0.15"/>
      <material name="green">
        <color rgba="0 1 0 1"/>
      </material>
    </visual>
  </link>
  <link name="no12_top_straw">
    <visual>
      <geometry>
        <cylinder length="0.3" radius="0.02"/>
      </geometry>
      <origin rpy="0 0 0" xyz="0 0 0.15"/>
      <material name="green">
        <color rgba="0 1 0 1"/>
      </material>
    </visual>
  </link>
  <joint name="no12_main_joint" type="revolute">
    <parent link="base_link"/>
    <child link="no12_bot_straw"/>
    <origin xyz="0.0728968627421 0.0684547105929 0"/>
    <axis xyz="0.0684547105929 -0.0728968627421 0"/>
    <limit effort="300" lower="-1.5707963268" upper="0" velocity="0.1"/>
    <mimic joint="master_main_joint" multiplier="1.0" offset="0.0"/>
    <dynamics damping="50" friction="1"/>
  </joint>
  <joint name="no12_slave_joint" type="revolute">
    <parent link="no12_bot_straw"/>
    <child link="no12_top_straw"/>
    <origin xyz="0 0 0.3"/>
    <axis xyz="0.0684547105929 -0.0728968627421 0"/>
    <limit effort="300" lower="-3.14159265359" upper="3.14159265359" velocity="0.1"/>
    <mimic joint="no12_main_joint" multiplier="-2.0" offset="0.0"/>
    <dynamics damping="50" friction="1"/>
  </joint>
  <link name="no13_bot_straw">
    <visual>
      <geometry>
        <cylinder length="0.3" radius="0.02"/>
      </geometry>
      <origin rpy="0 0 0" xyz="0 0 0.15"/>
      <material name="green">
        <color rgba="0 1 0 1"/>
      </material>
    </visual>
  </link>
  <link name="no13_top_straw">
    <visual>
      <geometry>
        <cylinder length="0.3" radius="0.02"/>
      </geometry>
      <origin rpy="0 0 0" xyz="0 0 0.15"/>
      <material name="green">
        <color rgba="0 1 0 1"/>
      </material>
    </visual>
  </link>
  <joint name="no13_main_joint" type="revolute">
    <parent link="base_link"/>
    <child link="no13_bot_straw"/>
    <origin xyz="0.0684547105929 0.0728968627421 0"/>
    <axis xyz="0.0728968627421 -0.0684547105929 0"/>
    <limit effort="300" lower="-1.5707963268" upper="0" velocity="0.1"/>
    <mimic joint="master_main_joint" multiplier="1.0" offset="0.0"/>
    <dynamics damping="50" friction="1"/>
  </joint>
  <joint name="no13_slave_joint" type="revolute">
    <parent link="no13_bot_straw"/>
    <child link="no13_top_straw"/>
    <origin xyz="0 0 0.3"/>
    <axis xyz="0.0728968627421 -0.0684547105929 0"/>
    <limit effort="300" lower="-3.14159265359" upper="3.14159265359" velocity="0.1"/>
    <mimic joint="no13_main_joint" multiplier="-2.0" offset="0.0"/>
    <dynamics damping="50" friction="1"/>
  </joint>
  <link name="no14_bot_straw">
    <visual>
      <geometry>
        <cylinder length="0.3" radius="0.02"/>
      </geometry>
      <origin rpy="0 0 0" xyz="0 0 0.15"/>
      <material name="green">
        <color rgba="0 1 0 1"/>
      </material>
    </visual>
  </link>
  <link name="no14_top_straw">
    <visual>
      <geometry>
        <cylinder length="0.3" radius="0.02"/>
      </geometry>
      <origin rpy="0 0 0" xyz="0 0 0.15"/>
      <material name="green">
        <color rgba="0 1 0 1"/>
      </material>
    </visual>
  </link>
  <joint name="no14_main_joint" type="revolute">
    <parent link="base_link"/>
    <child link="no14_bot_straw"/>
    <origin xyz="0.0637423989749 0.0770513242776 0"/>
    <axis xyz="0.0770513242776 -0.0637423989749 0"/>
    <limit effort="300" lower="-1.5707963268" upper="0" velocity="0.1"/>
    <mimic joint="master_main_joint" multiplier="1.0" offset="0.0"/>
    <dynamics damping="50" friction="1"/>
  </joint>
  <joint name="no14_slave_joint" type="revolute">
    <parent link="no14_bot_straw"/>
    <child link="no14_top_straw"/>
    <origin xyz="0 0 0.3"/>
    <axis xyz="0.0770513242776 -0.0637423989749 0"/>
    <limit effort="300" lower="-3.14159265359" upper="3.14159265359" velocity="0.1"/>
    <mimic joint="no14_main_joint" multiplier="-2.0" offset="0.0"/>
    <dynamics damping="50" friction="1"/>
  </joint>
  <link name="no15_bot_straw">
    <visual>
      <geometry>
        <cylinder length="0.3" radius="0.02"/>
      </geometry>
      <origin rpy="0 0 0" xyz="0 0 0.15"/>
      <material name="green">
        <color rgba="0 1 0 1"/>
      </material>
    </visual>
  </link>
  <link name="no15_top_straw">
    <visual>
      <geometry>
        <cylinder length="0.3" radius="0.02"/>
      </geometry>
      <origin rpy="0 0 0" xyz="0 0 0.15"/>
      <material name="green">
        <color rgba="0 1 0 1"/>
      </material>
    </visual>
  </link>
  <joint name="no15_main_joint" type="revolute">
    <parent link="base_link"/>
    <child link="no15_bot_straw"/>
    <origin xyz="0.0587785252292 0.0809016994375 0"/>
    <axis xyz="0.0809016994375 -0.0587785252292 0"/>
    <limit effort="300" lower="-1.5707963268" upper="0" velocity="0.1"/>
    <mimic joint="master_main_joint" multiplier="1.0" offset="0.0"/>
    <dynamics damping="50" friction="1"/>
  </joint>
  <joint name="no15_slave_joint" type="revolute">
    <parent link="no15_bot_straw"/>
    <child link="no15_top_straw"/>
    <origin xyz="0 0 0.3"/>
    <axis xyz="0.0809016994375 -0.0587785252292 0"/>
    <limit effort="300" lower="-3.14159265359" upper="3.14159265359" velocity="0.1"/>
    <mimic joint="no15_main_joint" multiplier="-2.0" offset="0.0"/>
    <dynamics damping="50" friction="1"/>
  </joint>
  <link name="no16_bot_straw">
    <visual>
      <geometry>
        <cylinder length="0.3" radius="0.02"/>
      </geometry>
      <origin rpy="0 0 0" xyz="0 0 0.15"/>
      <material name="green">
        <color rgba="0 1 0 1"/>
      </material>
    </visual>
  </link>
  <link name="no16_top_straw">
    <visual>
      <geometry>
        <cylinder length="0.3" radius="0.02"/>
      </geometry>
      <origin rpy="0 0 0" xyz="0 0 0.15"/>
      <material name="green">
        <color rgba="0 1 0 1"/>
      </material>
    </visual>
  </link>
  <joint name="no16_main_joint" type="revolute">
    <parent link="base_link"/>
    <child link="no16_bot_straw"/>
    <origin xyz="0.0535826794979 0.0844327925502 0"/>
    <axis xyz="0.0844327925502 -0.0535826794979 0"/>
    <limit effort="300" lower="-1.5707963268" upper="0" velocity="0.1"/>
    <mimic joint="master_main_joint" multiplier="1.0" offset="0.0"/>
    <dynamics damping="50" friction="1"/>
  </joint>
  <joint name="no16_slave_joint" type="revolute">
    <parent link="no16_bot_straw"/>
    <child link="no16_top_straw"/>
    <origin xyz="0 0 0.3"/>
    <axis xyz="0.0844327925502 -0.0535826794979 0"/>
    <limit effort="300" lower="-3.14159265359" upper="3.14159265359" velocity="0.1"/>
    <mimic joint="no16_main_joint" multiplier="-2.0" offset="0.0"/>
    <dynamics damping="50" friction="1"/>
  </joint>
  <link name="no17_bot_straw">
    <visual>
      <geometry>
        <cylinder length="0.3" radius="0.02"/>
      </geometry>
      <origin rpy="0 0 0" xyz="0 0 0.15"/>
      <material name="green">
        <color rgba="0 1 0 1"/>
      </material>
    </visual>
  </link>
  <link name="no17_top_straw">
    <visual>
      <geometry>
        <cylinder length="0.3" radius="0.02"/>
      </geometry>
      <origin rpy="0 0 0" xyz="0 0 0.15"/>
      <material name="green">
        <color rgba="0 1 0 1"/>
      </material>
    </visual>
  </link>
  <joint name="no17_main_joint" type="revolute">
    <parent link="base_link"/>
    <child link="no17_bot_straw"/>
    <origin xyz="0.0481753674102 0.0876306680044 0"/>
    <axis xyz="0.0876306680044 -0.0481753674102 0"/>
    <limit effort="300" lower="-1.5707963268" upper="0" velocity="0.1"/>
    <mimic joint="master_main_joint" multiplier="1.0" offset="0.0"/>
    <dynamics damping="50" friction="1"/>
  </joint>
  <joint name="no17_slave_joint" type="revolute">
    <parent link="no17_bot_straw"/>
    <child link="no17_top_straw"/>
    <origin xyz="0 0 0.3"/>
    <axis xyz="0.0876306680044 -0.0481753674102 0"/>
    <limit effort="300" lower="-3.14159265359" upper="3.14159265359" velocity="0.1"/>
    <mimic joint="no17_main_joint" multiplier="-2.0" offset="0.0"/>
    <dynamics damping="50" friction="1"/>
  </joint>
  <link name="no18_bot_straw">
    <visual>
      <geometry>
        <cylinder length="0.3" radius="0.02"/>
      </geometry>
      <origin rpy="0 0 0" xyz="0 0 0.15"/>
      <material name="green">
        <color rgba="0 1 0 1"/>
      </material>
    </visual>
  </link>
  <link name="no18_top_straw">
    <visual>
      <geometry>
        <cylinder length="0.3" radius="0.02"/>
      </geometry>
      <origin rpy="0 0 0" xyz="0 0 0.15"/>
      <material name="green">
        <color rgba="0 1 0 1"/>
      </material>
    </visual>
  </link>
  <joint name="no18_main_joint" type="revolute">
    <parent link="base_link"/>
    <child link="no18_bot_straw"/>
    <origin xyz="0.0425779291565 0.0904827052466 0"/>
    <axis xyz="0.0904827052466 -0.0425779291565 0"/>
    <limit effort="300" lower="-1.5707963268" upper="0" velocity="0.1"/>
    <mimic joint="master_main_joint" multiplier="1.0" offset="0.0"/>
    <dynamics damping="50" friction="1"/>
  </joint>
  <joint name="no18_slave_joint" type="revolute">
    <parent link="no18_bot_straw"/>
    <child link="no18_top_straw"/>
    <origin xyz="0 0 0.3"/>
    <axis xyz="0.0904827052466 -0.0425779291565 0"/>
    <limit effort="300" lower="-3.14159265359" upper="3.14159265359" velocity="0.1"/>
    <mimic joint="no18_main_joint" multiplier="-2.0" offset="0.0"/>
    <dynamics damping="50" friction="1"/>
  </joint>
  <link name="no19_bot_straw">
    <visual>
      <geometry>
        <cylinder length="0.3" radius="0.02"/>
      </geometry>
      <origin rpy="0 0 0" xyz="0 0 0.15"/>
      <material name="green">
        <color rgba="0 1 0 1"/>
      </material>
    </visual>
  </link>
  <link name="no19_top_straw">
    <visual>
      <geometry>
        <cylinder length="0.3" radius="0.02"/>
      </geometry>
      <origin rpy="0 0 0" xyz="0 0 0.15"/>
      <material name="green">
        <color rgba="0 1 0 1"/>
      </material>
    </visual>
  </link>
  <joint name="no19_main_joint" type="revolute">
    <parent link="base_link"/>
    <child link="no19_bot_straw"/>
    <origin xyz="0.0368124552685 0.0929776485888 0"/>
    <axis xyz="0.0929776485888 -0.0368124552685 0"/>
    <limit effort="300" lower="-1.5707963268" upper="0" velocity="0.1"/>
    <mimic joint="master_main_joint" multiplier="1.0" offset="0.0"/>
    <dynamics damping="50" friction="1"/>
  </joint>
  <joint name="no19_slave_joint" type="revolute">
    <parent link="no19_bot_straw"/>
    <child link="no19_top_straw"/>
    <origin xyz="0 0 0.3"/>
    <axis xyz="0.0929776485888 -0.0368124552685 0"/>
    <limit effort="300" lower="-3.14159265359" upper="3.14159265359" velocity="0.1"/>
    <mimic joint="no19_main_joint" multiplier="-2.0" offset="0.0"/>
    <dynamics damping="50" friction="1"/>
  </joint>
  <link name="no20_bot_straw">
    <visual>
      <geometry>
        <cylinder length="0.3" radius="0.02"/>
      </geometry>
      <origin rpy="0 0 0" xyz="0 0 0.15"/>
      <material name="green">
        <color rgba="0 1 0 1"/>
      </material>
    </visual>
  </link>
  <link name="no20_top_straw">
    <visual>
      <geometry>
        <cylinder length="0.3" radius="0.02"/>
      </geometry>
      <origin rpy="0 0 0" xyz="0 0 0.15"/>
      <material name="green">
        <color rgba="0 1 0 1"/>
      </material>
    </visual>
  </link>
  <joint name="no20_main_joint" type="revolute">
    <parent link="base_link"/>
    <child link="no20_bot_straw"/>
    <origin xyz="0.0309016994375 0.0951056516295 0"/>
    <axis xyz="0.0951056516295 -0.0309016994375 0"/>
    <limit effort="300" lower="-1.5707963268" upper="0" velocity="0.1"/>
    <mimic joint="master_main_joint" multiplier="1.0" offset="0.0"/>
    <dynamics damping="50" friction="1"/>
  </joint>
  <joint name="no20_slave_joint" type="revolute">
    <parent link="no20_bot_straw"/>
    <child link="no20_top_straw"/>
    <origin xyz="0 0 0.3"/>
    <axis xyz="0.0951056516295 -0.0309016994375 0"/>
    <limit effort="300" lower="-3.14159265359" upper="3.14159265359" velocity="0.1"/>
    <mimic joint="no20_main_joint" multiplier="-2.0" offset="0.0"/>
    <dynamics damping="50" friction="1"/>
  </joint>
  <link name="no21_bot_straw">
    <visual>
      <geometry>
        <cylinder length="0.3" radius="0.02"/>
      </geometry>
      <origin rpy="0 0 0" xyz="0 0 0.15"/>
      <material name="green">
        <color rgba="0 1 0 1"/>
      </material>
    </visual>
  </link>
  <link name="no21_top_straw">
    <visual>
      <geometry>
        <cylinder length="0.3" radius="0.02"/>
      </geometry>
      <origin rpy="0 0 0" xyz="0 0 0.15"/>
      <material name="green">
        <color rgba="0 1 0 1"/>
      </material>
    </visual>
  </link>
  <joint name="no21_main_joint" type="revolute">
    <parent link="base_link"/>
    <child link="no21_bot_straw"/>
    <origin xyz="0.0248689887165 0.0968583161129 0"/>
    <axis xyz="0.0968583161129 -0.0248689887165 0"/>
    <limit effort="300" lower="-1.5707963268" upper="0" velocity="0.1"/>
    <mimic joint="master_main_joint" multiplier="1.0" offset="0.0"/>
    <dynamics damping="50" friction="1"/>
  </joint>
  <joint name="no21_slave_joint" type="revolute">
    <parent link="no21_bot_straw"/>
    <child link="no21_top_straw"/>
    <origin xyz="0 0 0.3"/>
    <axis xyz="0.0968583161129 -0.0248689887165 0"/>
    <limit effort="300" lower="-3.14159265359" upper="3.14159265359" velocity="0.1"/>
    <mimic joint="no21_main_joint" multiplier="-2.0" offset="0.0"/>
    <dynamics damping="50" friction="1"/>
  </joint>
  <link name="no22_bot_straw">
    <visual>
      <geometry>
        <cylinder length="0.3" radius="0.02"/>
      </geometry>
      <origin rpy="0 0 0" xyz="0 0 0.15"/>
      <material name="green">
        <color rgba="0 1 0 1"/>
      </material>
    </visual>
  </link>
  <link name="no22_top_straw">
    <visual>
      <geometry>
        <cylinder length="0.3" radius="0.02"/>
      </geometry>
      <origin rpy="0 0 0" xyz="0 0 0.15"/>
      <material name="green">
        <color rgba="0 1 0 1"/>
      </material>
    </visual>
  </link>
  <joint name="no22_main_joint" type="revolute">
    <parent link="base_link"/>
    <child link="no22_bot_straw"/>
    <origin xyz="0.0187381314586 0.0982287250729 0"/>
    <axis xyz="0.0982287250729 -0.0187381314586 0"/>
    <limit effort="300" lower="-1.5707963268" upper="0" velocity="0.1"/>
    <mimic joint="master_main_joint" multiplier="1.0" offset="0.0"/>
    <dynamics damping="50" friction="1"/>
  </joint>
  <joint name="no22_slave_joint" type="revolute">
    <parent link="no22_bot_straw"/>
    <child link="no22_top_straw"/>
    <origin xyz="0 0 0.3"/>
    <axis xyz="0.0982287250729 -0.0187381314586 0"/>
    <limit effort="300" lower="-3.14159265359" upper="3.14159265359" velocity="0.1"/>
    <mimic joint="no22_main_joint" multiplier="-2.0" offset="0.0"/>
    <dynamics damping="50" friction="1"/>
  </joint>
  <link name="no23_bot_straw">
    <visual>
      <geometry>
        <cylinder length="0.3" radius="0.02"/>
      </geometry>
      <origin rpy="0 0 0" xyz="0 0 0.15"/>
      <material name="green">
        <color rgba="0 1 0 1"/>
      </material>
    </visual>
  </link>
  <link name="no23_top_straw">
    <visual>
      <geometry>
        <cylinder length="0.3" radius="0.02"/>
      </geometry>
      <origin rpy="0 0 0" xyz="0 0 0.15"/>
      <material name="green">
        <color rgba="0 1 0 1"/>
      </material>
    </visual>
  </link>
  <joint name="no23_main_joint" type="revolute">
    <parent link="base_link"/>
    <child link="no23_bot_straw"/>
    <origin xyz="0.0125333233564 0.0992114701314 0"/>
    <axis xyz="0.0992114701314 -0.0125333233564 0"/>
    <limit effort="300" lower="-1.5707963268" upper="0" velocity="0.1"/>
    <mimic joint="master_main_joint" multiplier="1.0" offset="0.0"/>
    <dynamics damping="50" friction="1"/>
  </joint>
  <joint name="no23_slave_joint" type="revolute">
    <parent link="no23_bot_straw"/>
    <child link="no23_top_straw"/>
    <origin xyz="0 0 0.3"/>
    <axis xyz="0.0992114701314 -0.0125333233564 0"/>
    <limit effort="300" lower="-3.14159265359" upper="3.14159265359" velocity="0.1"/>
    <mimic joint="no23_main_joint" multiplier="-2.0" offset="0.0"/>
    <dynamics damping="50" friction="1"/>
  </joint>
  <link name="no24_bot_straw">
    <visual>
      <geometry>
        <cylinder length="0.3" radius="0.02"/>
      </geometry>
      <origin rpy="0 0 0" xyz="0 0 0.15"/>
      <material name="green">
        <color rgba="0 1 0 1"/>
      </material>
    </visual>
  </link>
  <link name="no24_top_straw">
    <visual>
      <geometry>
        <cylinder length="0.3" radius="0.02"/>
      </geometry>
      <origin rpy="0 0 0" xyz="0 0 0.15"/>
      <material name="green">
        <color rgba="0 1 0 1"/>
      </material>
    </visual>
  </link>
  <joint name="no24_main_joint" type="revolute">
    <parent link="base_link"/>
    <child link="no24_bot_straw"/>
    <origin xyz="0.00627905195292 0.0998026728428 0"/>
    <axis xyz="0.0998026728428 -0.00627905195292 0"/>
    <limit effort="300" lower="-1.5707963268" upper="0" velocity="0.1"/>
    <mimic joint="master_main_joint" multiplier="1.0" offset="0.0"/>
    <dynamics damping="50" friction="1"/>
  </joint>
  <joint name="no24_slave_joint" type="revolute">
    <parent link="no24_bot_straw"/>
    <child link="no24_top_straw"/>
    <origin xyz="0 0 0.3"/>
    <axis xyz="0.0998026728428 -0.00627905195292 0"/>
    <limit effort="300" lower="-3.14159265359" upper="3.14159265359" velocity="0.1"/>
    <mimic joint="no24_main_joint" multiplier="-2.0" offset="0.0"/>
    <dynamics damping="50" friction="1"/>
  </joint>
  <link name="no25_bot_straw">
    <visual>
      <geometry>
        <cylinder length="0.3" radius="0.02"/>
      </geometry>
      <origin rpy="0 0 0" xyz="0 0 0.15"/>
      <material name="green">
        <color rgba="0 1 0 1"/>
      </material>
    </visual>
  </link>
  <link name="no25_top_straw">
    <visual>
      <geometry>
        <cylinder length="0.3" radius="0.02"/>
      </geometry>
      <origin rpy="0 0 0" xyz="0 0 0.15"/>
      <material name="green">
        <color rgba="0 1 0 1"/>
      </material>
    </visual>
  </link>
  <joint name="no25_main_joint" type="revolute">
    <parent link="base_link"/>
    <child link="no25_bot_straw"/>
    <origin xyz="-1.03411553555e-14 0.1 0"/>
    <axis xyz="0.1 1.03411553555e-14 0"/>
    <limit effort="300" lower="-1.5707963268" upper="0" velocity="0.1"/>
    <mimic joint="master_main_joint" multiplier="1.0" offset="0.0"/>
    <dynamics damping="50" friction="1"/>
  </joint>
  <joint name="no25_slave_joint" type="revolute">
    <parent link="no25_bot_straw"/>
    <child link="no25_top_straw"/>
    <origin xyz="0 0 0.3"/>
    <axis xyz="0.1 1.03411553555e-14 0"/>
    <limit effort="300" lower="-3.14159265359" upper="3.14159265359" velocity="0.1"/>
    <mimic joint="no25_main_joint" multiplier="-2.0" offset="0.0"/>
    <dynamics damping="50" friction="1"/>
  </joint>
  <link name="no26_bot_straw">
    <visual>
      <geometry>
        <cylinder length="0.3" radius="0.02"/>
      </geometry>
      <origin rpy="0 0 0" xyz="0 0 0.15"/>
      <material name="green">
        <color rgba="0 1 0 1"/>
      </material>
    </visual>
  </link>
  <link name="no26_top_straw">
    <visual>
      <geometry>
        <cylinder length="0.3" radius="0.02"/>
      </geometry>
      <origin rpy="0 0 0" xyz="0 0 0.15"/>
      <material name="green">
        <color rgba="0 1 0 1"/>
      </material>
    </visual>
  </link>
  <joint name="no26_main_joint" type="revolute">
    <parent link="base_link"/>
    <child link="no26_bot_straw"/>
    <origin xyz="-0.00627905195294 0.0998026728428 0"/>
    <axis xyz="0.0998026728428 0.00627905195294 0"/>
    <limit effort="300" lower="-1.5707963268" upper="0" velocity="0.1"/>
    <mimic joint="master_main_joint" multiplier="1.0" offset="0.0"/>
    <dynamics damping="50" friction="1"/>
  </joint>
  <joint name="no26_slave_joint" type="revolute">
    <parent link="no26_bot_straw"/>
    <child link="no26_top_straw"/>
    <origin xyz="0 0 0.3"/>
    <axis xyz="0.0998026728428 0.00627905195294 0"/>
    <limit effort="300" lower="-3.14159265359" upper="3.14159265359" velocity="0.1"/>
    <mimic joint="no26_main_joint" multiplier="-2.0" offset="0.0"/>
    <dynamics damping="50" friction="1"/>
  </joint>
  <link name="no27_bot_straw">
    <visual>
      <geometry>
        <cylinder length="0.3" radius="0.02"/>
      </geometry>
      <origin rpy="0 0 0" xyz="0 0 0.15"/>
      <material name="green">
        <color rgba="0 1 0 1"/>
      </material>
    </visual>
  </link>
  <link name="no27_top_straw">
    <visual>
      <geometry>
        <cylinder length="0.3" radius="0.02"/>
      </geometry>
      <origin rpy="0 0 0" xyz="0 0 0.15"/>
      <material name="green">
        <color rgba="0 1 0 1"/>
      </material>
    </visual>
  </link>
  <joint name="no27_main_joint" type="revolute">
    <parent link="base_link"/>
    <child link="no27_bot_straw"/>
    <origin xyz="-0.0125333233564 0.0992114701314 0"/>
    <axis xyz="0.0992114701314 0.0125333233564 0"/>
    <limit effort="300" lower="-1.5707963268" upper="0" velocity="0.1"/>
    <mimic joint="master_main_joint" multiplier="1.0" offset="0.0"/>
    <dynamics damping="50" friction="1"/>
  </joint>
  <joint name="no27_slave_joint" type="revolute">
    <parent link="no27_bot_straw"/>
    <child link="no27_top_straw"/>
    <origin xyz="0 0 0.3"/>
    <axis xyz="0.0992114701314 0.0125333233564 0"/>
    <limit effort="300" lower="-3.14159265359" upper="3.14159265359" velocity="0.1"/>
    <mimic joint="no27_main_joint" multiplier="-2.0" offset="0.0"/>
    <dynamics damping="50" friction="1"/>
  </joint>
  <link name="no28_bot_straw">
    <visual>
      <geometry>
        <cylinder length="0.3" radius="0.02"/>
      </geometry>
      <origin rpy="0 0 0" xyz="0 0 0.15"/>
      <material name="green">
        <color rgba="0 1 0 1"/>
      </material>
    </visual>
  </link>
  <link name="no28_top_straw">
    <visual>
      <geometry>
        <cylinder length="0.3" radius="0.02"/>
      </geometry>
      <origin rpy="0 0 0" xyz="0 0 0.15"/>
      <material name="green">
        <color rgba="0 1 0 1"/>
      </material>
    </visual>
  </link>
  <joint name="no28_main_joint" type="revolute">
    <parent link="base_link"/>
    <child link="no28_bot_straw"/>
    <origin xyz="-0.0187381314586 0.0982287250729 0"/>
    <axis xyz="0.0982287250729 0.0187381314586 0"/>
    <limit effort="300" lower="-1.5707963268" upper="0" velocity="0.1"/>
    <mimic joint="master_main_joint" multiplier="1.0" offset="0.0"/>
    <dynamics damping="50" friction="1"/>
  </joint>
  <joint name="no28_slave_joint" type="revolute">
    <parent link="no28_bot_straw"/>
    <child link="no28_top_straw"/>
    <origin xyz="0 0 0.3"/>
    <axis xyz="0.0982287250729 0.0187381314586 0"/>
    <limit effort="300" lower="-3.14159265359" upper="3.14159265359" velocity="0.1"/>
    <mimic joint="no28_main_joint" multiplier="-2.0" offset="0.0"/>
    <dynamics damping="50" friction="1"/>
  </joint>
  <link name="no29_bot_straw">
    <visual>
      <geometry>
        <cylinder length="0.3" radius="0.02"/>
      </geometry>
      <origin rpy="0 0 0" xyz="0 0 0.15"/>
      <material name="green">
        <color rgba="0 1 0 1"/>
      </material>
    </visual>
  </link>
  <link name="no29_top_straw">
    <visual>
      <geometry>
        <cylinder length="0.3" radius="0.02"/>
      </geometry>
      <origin rpy="0 0 0" xyz="0 0 0.15"/>
      <material name="green">
        <color rgba="0 1 0 1"/>
      </material>
    </visual>
  </link>
  <joint name="no29_main_joint" type="revolute">
    <parent link="base_link"/>
    <child link="no29_bot_straw"/>
    <origin xyz="-0.0248689887165 0.0968583161129 0"/>
    <axis xyz="0.0968583161129 0.0248689887165 0"/>
    <limit effort="300" lower="-1.5707963268" upper="0" velocity="0.1"/>
    <mimic joint="master_main_joint" multiplier="1.0" offset="0.0"/>
    <dynamics damping="50" friction="1"/>
  </joint>
  <joint name="no29_slave_joint" type="revolute">
    <parent link="no29_bot_straw"/>
    <child link="no29_top_straw"/>
    <origin xyz="0 0 0.3"/>
    <axis xyz="0.0968583161129 0.0248689887165 0"/>
    <limit effort="300" lower="-3.14159265359" upper="3.14159265359" velocity="0.1"/>
    <mimic joint="no29_main_joint" multiplier="-2.0" offset="0.0"/>
    <dynamics damping="50" friction="1"/>
  </joint>
  <link name="no30_bot_straw">
    <visual>
      <geometry>
        <cylinder length="0.3" radius="0.02"/>
      </geometry>
      <origin rpy="0 0 0" xyz="0 0 0.15"/>
      <material name="green">
        <color rgba="0 1 0 1"/>
      </material>
    </visual>
  </link>
  <link name="no30_top_straw">
    <visual>
      <geometry>
        <cylinder length="0.3" radius="0.02"/>
      </geometry>
      <origin rpy="0 0 0" xyz="0 0 0.15"/>
      <material name="green">
        <color rgba="0 1 0 1"/>
      </material>
    </visual>
  </link>
  <joint name="no30_main_joint" type="revolute">
    <parent link="base_link"/>
    <child link="no30_bot_straw"/>
    <origin xyz="-0.0309016994375 0.0951056516295 0"/>
    <axis xyz="0.0951056516295 0.0309016994375 0"/>
    <limit effort="300" lower="-1.5707963268" upper="0" velocity="0.1"/>
    <mimic joint="master_main_joint" multiplier="1.0" offset="0.0"/>
    <dynamics damping="50" friction="1"/>
  </joint>
  <joint name="no30_slave_joint" type="revolute">
    <parent link="no30_bot_straw"/>
    <child link="no30_top_straw"/>
    <origin xyz="0 0 0.3"/>
    <axis xyz="0.0951056516295 0.0309016994375 0"/>
    <limit effort="300" lower="-3.14159265359" upper="3.14159265359" velocity="0.1"/>
    <mimic joint="no30_main_joint" multiplier="-2.0" offset="0.0"/>
    <dynamics damping="50" friction="1"/>
  </joint>
  <link name="no31_bot_straw">
    <visual>
      <geometry>
        <cylinder length="0.3" radius="0.02"/>
      </geometry>
      <origin rpy="0 0 0" xyz="0 0 0.15"/>
      <material name="green">
        <color rgba="0 1 0 1"/>
      </material>
    </visual>
  </link>
  <link name="no31_top_straw">
    <visual>
      <geometry>
        <cylinder length="0.3" radius="0.02"/>
      </geometry>
      <origin rpy="0 0 0" xyz="0 0 0.15"/>
      <material name="green">
        <color rgba="0 1 0 1"/>
      </material>
    </visual>
  </link>
  <joint name="no31_main_joint" type="revolute">
    <parent link="base_link"/>
    <child link="no31_bot_straw"/>
    <origin xyz="-0.0368124552685 0.0929776485888 0"/>
    <axis xyz="0.0929776485888 0.0368124552685 0"/>
    <limit effort="300" lower="-1.5707963268" upper="0" velocity="0.1"/>
    <mimic joint="master_main_joint" multiplier="1.0" offset="0.0"/>
    <dynamics damping="50" friction="1"/>
  </joint>
  <joint name="no31_slave_joint" type="revolute">
    <parent link="no31_bot_straw"/>
    <child link="no31_top_straw"/>
    <origin xyz="0 0 0.3"/>
    <axis xyz="0.0929776485888 0.0368124552685 0"/>
    <limit effort="300" lower="-3.14159265359" upper="3.14159265359" velocity="0.1"/>
    <mimic joint="no31_main_joint" multiplier="-2.0" offset="0.0"/>
    <dynamics damping="50" friction="1"/>
  </joint>
  <link name="no32_bot_straw">
    <visual>
      <geometry>
        <cylinder length="0.3" radius="0.02"/>
      </geometry>
      <origin rpy="0 0 0" xyz="0 0 0.15"/>
      <material name="green">
        <color rgba="0 1 0 1"/>
      </material>
    </visual>
  </link>
  <link name="no32_top_straw">
    <visual>
      <geometry>
        <cylinder length="0.3" radius="0.02"/>
      </geometry>
      <origin rpy="0 0 0" xyz="0 0 0.15"/>
      <material name="green">
        <color rgba="0 1 0 1"/>
      </material>
    </visual>
  </link>
  <joint name="no32_main_joint" type="revolute">
    <parent link="base_link"/>
    <child link="no32_bot_straw"/>
    <origin xyz="-0.0425779291565 0.0904827052466 0"/>
    <axis xyz="0.0904827052466 0.0425779291565 0"/>
    <limit effort="300" lower="-1.5707963268" upper="0" velocity="0.1"/>
    <mimic joint="master_main_joint" multiplier="1.0" offset="0.0"/>
    <dynamics damping="50" friction="1"/>
  </joint>
  <joint name="no32_slave_joint" type="revolute">
    <parent link="no32_bot_straw"/>
    <child link="no32_top_straw"/>
    <origin xyz="0 0 0.3"/>
    <axis xyz="0.0904827052466 0.0425779291565 0"/>
    <limit effort="300" lower="-3.14159265359" upper="3.14159265359" velocity="0.1"/>
    <mimic joint="no32_main_joint" multiplier="-2.0" offset="0.0"/>
    <dynamics damping="50" friction="1"/>
  </joint>
  <link name="no33_bot_straw">
    <visual>
      <geometry>
        <cylinder length="0.3" radius="0.02"/>
      </geometry>
      <origin rpy="0 0 0" xyz="0 0 0.15"/>
      <material name="green">
        <color rgba="0 1 0 1"/>
      </material>
    </visual>
  </link>
  <link name="no33_top_straw">
    <visual>
      <geometry>
        <cylinder length="0.3" radius="0.02"/>
      </geometry>
      <origin rpy="0 0 0" xyz="0 0 0.15"/>
      <material name="green">
        <color rgba="0 1 0 1"/>
      </material>
    </visual>
  </link>
  <joint name="no33_main_joint" type="revolute">
    <parent link="base_link"/>
    <child link="no33_bot_straw"/>
    <origin xyz="-0.0481753674102 0.0876306680044 0"/>
    <axis xyz="0.0876306680044 0.0481753674102 0"/>
    <limit effort="300" lower="-1.5707963268" upper="0" velocity="0.1"/>
    <mimic joint="master_main_joint" multiplier="1.0" offset="0.0"/>
    <dynamics damping="50" friction="1"/>
  </joint>
  <joint name="no33_slave_joint" type="revolute">
    <parent link="no33_bot_straw"/>
    <child link="no33_top_straw"/>
    <origin xyz="0 0 0.3"/>
    <axis xyz="0.0876306680044 0.0481753674102 0"/>
    <limit effort="300" lower="-3.14159265359" upper="3.14159265359" velocity="0.1"/>
    <mimic joint="no33_main_joint" multiplier="-2.0" offset="0.0"/>
    <dynamics damping="50" friction="1"/>
  </joint>
  <link name="no34_bot_straw">
    <visual>
      <geometry>
        <cylinder length="0.3" radius="0.02"/>
      </geometry>
      <origin rpy="0 0 0" xyz="0 0 0.15"/>
      <material name="green">
        <color rgba="0 1 0 1"/>
      </material>
    </visual>
  </link>
  <link name="no34_top_straw">
    <visual>
      <geometry>
        <cylinder length="0.3" radius="0.02"/>
      </geometry>
      <origin rpy="0 0 0" xyz="0 0 0.15"/>
      <material name="green">
        <color rgba="0 1 0 1"/>
      </material>
    </visual>
  </link>
  <joint name="no34_main_joint" type="revolute">
    <parent link="base_link"/>
    <child link="no34_bot_straw"/>
    <origin xyz="-0.0535826794979 0.0844327925502 0"/>
    <axis xyz="0.0844327925502 0.0535826794979 0"/>
    <limit effort="300" lower="-1.5707963268" upper="0" velocity="0.1"/>
    <mimic joint="master_main_joint" multiplier="1.0" offset="0.0"/>
    <dynamics damping="50" friction="1"/>
  </joint>
  <joint name="no34_slave_joint" type="revolute">
    <parent link="no34_bot_straw"/>
    <child link="no34_top_straw"/>
    <origin xyz="0 0 0.3"/>
    <axis xyz="0.0844327925502 0.0535826794979 0"/>
    <limit effort="300" lower="-3.14159265359" upper="3.14159265359" velocity="0.1"/>
    <mimic joint="no34_main_joint" multiplier="-2.0" offset="0.0"/>
    <dynamics damping="50" friction="1"/>
  </joint>
  <link name="no35_bot_straw">
    <visual>
      <geometry>
        <cylinder length="0.3" radius="0.02"/>
      </geometry>
      <origin rpy="0 0 0" xyz="0 0 0.15"/>
      <material name="green">
        <color rgba="0 1 0 1"/>
      </material>
    </visual>
  </link>
  <link name="no35_top_straw">
    <visual>
      <geometry>
        <cylinder length="0.3" radius="0.02"/>
      </geometry>
      <origin rpy="0 0 0" xyz="0 0 0.15"/>
      <material name="green">
        <color rgba="0 1 0 1"/>
      </material>
    </visual>
  </link>
  <joint name="no35_main_joint" type="revolute">
    <parent link="base_link"/>
    <child link="no35_bot_straw"/>
    <origin xyz="-0.0587785252293 0.0809016994375 0"/>
    <axis xyz="0.0809016994375 0.0587785252293 0"/>
    <limit effort="300" lower="-1.5707963268" upper="0" velocity="0.1"/>
    <mimic joint="master_main_joint" multiplier="1.0" offset="0.0"/>
    <dynamics damping="50" friction="1"/>
  </joint>
  <joint name="no35_slave_joint" type="revolute">
    <parent link="no35_bot_straw"/>
    <child link="no35_top_straw"/>
    <origin xyz="0 0 0.3"/>
    <axis xyz="0.0809016994375 0.0587785252293 0"/>
    <limit effort="300" lower="-3.14159265359" upper="3.14159265359" velocity="0.1"/>
    <mimic joint="no35_main_joint" multiplier="-2.0" offset="0.0"/>
    <dynamics damping="50" friction="1"/>
  </joint>
  <link name="no36_bot_straw">
    <visual>
      <geometry>
        <cylinder length="0.3" radius="0.02"/>
      </geometry>
      <origin rpy="0 0 0" xyz="0 0 0.15"/>
      <material name="green">
        <color rgba="0 1 0 1"/>
      </material>
    </visual>
  </link>
  <link name="no36_top_straw">
    <visual>
      <geometry>
        <cylinder length="0.3" radius="0.02"/>
      </geometry>
      <origin rpy="0 0 0" xyz="0 0 0.15"/>
      <material name="green">
        <color rgba="0 1 0 1"/>
      </material>
    </visual>
  </link>
  <joint name="no36_main_joint" type="revolute">
    <parent link="base_link"/>
    <child link="no36_bot_straw"/>
    <origin xyz="-0.0637423989749 0.0770513242776 0"/>
    <axis xyz="0.0770513242776 0.0637423989749 0"/>
    <limit effort="300" lower="-1.5707963268" upper="0" velocity="0.1"/>
    <mimic joint="master_main_joint" multiplier="1.0" offset="0.0"/>
    <dynamics damping="50" friction="1"/>
  </joint>
  <joint name="no36_slave_joint" type="revolute">
    <parent link="no36_bot_straw"/>
    <child link="no36_top_straw"/>
    <origin xyz="0 0 0.3"/>
    <axis xyz="0.0770513242776 0.0637423989749 0"/>
    <limit effort="300" lower="-3.14159265359" upper="3.14159265359" velocity="0.1"/>
    <mimic joint="no36_main_joint" multiplier="-2.0" offset="0.0"/>
    <dynamics damping="50" friction="1"/>
  </joint>
  <link name="no37_bot_straw">
    <visual>
      <geometry>
        <cylinder length="0.3" radius="0.02"/>
      </geometry>
      <origin rpy="0 0 0" xyz="0 0 0.15"/>
      <material name="green">
        <color rgba="0 1 0 1"/>
      </material>
    </visual>
  </link>
  <link name="no37_top_straw">
    <visual>
      <geometry>
        <cylinder length="0.3" radius="0.02"/>
      </geometry>
      <origin rpy="0 0 0" xyz="0 0 0.15"/>
      <material name="green">
        <color rgba="0 1 0 1"/>
      </material>
    </visual>
  </link>
  <joint name="no37_main_joint" type="revolute">
    <parent link="base_link"/>
    <child link="no37_bot_straw"/>
    <origin xyz="-0.0684547105929 0.0728968627421 0"/>
    <axis xyz="0.0728968627421 0.0684547105929 0"/>
    <limit effort="300" lower="-1.5707963268" upper="0" velocity="0.1"/>
    <mimic joint="master_main_joint" multiplier="1.0" offset="0.0"/>
    <dynamics damping="50" friction="1"/>
  </joint>
  <joint name="no37_slave_joint" type="revolute">
    <parent link="no37_bot_straw"/>
    <child link="no37_top_straw"/>
    <origin xyz="0 0 0.3"/>
    <axis xyz="0.0728968627421 0.0684547105929 0"/>
    <limit effort="300" lower="-3.14159265359" upper="3.14159265359" velocity="0.1"/>
    <mimic joint="no37_main_joint" multiplier="-2.0" offset="0.0"/>
    <dynamics damping="50" friction="1"/>
  </joint>
  <link name="no38_bot_straw">
    <visual>
      <geometry>
        <cylinder length="0.3" radius="0.02"/>
      </geometry>
      <origin rpy="0 0 0" xyz="0 0 0.15"/>
      <material name="green">
        <color rgba="0 1 0 1"/>
      </material>
    </visual>
  </link>
  <link name="no38_top_straw">
    <visual>
      <geometry>
        <cylinder length="0.3" radius="0.02"/>
      </geometry>
      <origin rpy="0 0 0" xyz="0 0 0.15"/>
      <material name="green">
        <color rgba="0 1 0 1"/>
      </material>
    </visual>
  </link>
  <joint name="no38_main_joint" type="revolute">
    <parent link="base_link"/>
    <child link="no38_bot_straw"/>
    <origin xyz="-0.0728968627422 0.0684547105929 0"/>
    <axis xyz="0.0684547105929 0.0728968627422 0"/>
    <limit effort="300" lower="-1.5707963268" upper="0" velocity="0.1"/>
    <mimic joint="master_main_joint" multiplier="1.0" offset="0.0"/>
    <dynamics damping="50" friction="1"/>
  </joint>
  <joint name="no38_slave_joint" type="revolute">
    <parent link="no38_bot_straw"/>
    <child link="no38_top_straw"/>
    <origin xyz="0 0 0.3"/>
    <axis xyz="0.0684547105929 0.0728968627422 0"/>
    <limit effort="300" lower="-3.14159265359" upper="3.14159265359" velocity="0.1"/>
    <mimic joint="no38_main_joint" multiplier="-2.0" offset="0.0"/>
    <dynamics damping="50" friction="1"/>
  </joint>
  <link name="no39_bot_straw">
    <visual>
      <geometry>
        <cylinder length="0.3" radius="0.02"/>
      </geometry>
      <origin rpy="0 0 0" xyz="0 0 0.15"/>
      <material name="green">
        <color rgba="0 1 0 1"/>
      </material>
    </visual>
  </link>
  <link name="no39_top_straw">
    <visual>
      <geometry>
        <cylinder length="0.3" radius="0.02"/>
      </geometry>
      <origin rpy="0 0 0" xyz="0 0 0.15"/>
      <material name="green">
        <color rgba="0 1 0 1"/>
      </material>
    </visual>
  </link>
  <joint name="no39_main_joint" type="revolute">
    <parent link="base_link"/>
    <child link="no39_bot_straw"/>
    <origin xyz="-0.0770513242776 0.0637423989749 0"/>
    <axis xyz="0.0637423989749 0.0770513242776 0"/>
    <limit effort="300" lower="-1.5707963268" upper="0" velocity="0.1"/>
    <mimic joint="master_main_joint" multiplier="1.0" offset="0.0"/>
    <dynamics damping="50" friction="1"/>
  </joint>
  <joint name="no39_slave_joint" type="revolute">
    <parent link="no39_bot_straw"/>
    <child link="no39_top_straw"/>
    <origin xyz="0 0 0.3"/>
    <axis xyz="0.0637423989749 0.0770513242776 0"/>
    <limit effort="300" lower="-3.14159265359" upper="3.14159265359" velocity="0.1"/>
    <mimic joint="no39_main_joint" multiplier="-2.0" offset="0.0"/>
    <dynamics damping="50" friction="1"/>
  </joint>
  <link name="no40_bot_straw">
    <visual>
      <geometry>
        <cylinder length="0.3" radius="0.02"/>
      </geometry>
      <origin rpy="0 0 0" xyz="0 0 0.15"/>
      <material name="green">
        <color rgba="0 1 0 1"/>
      </material>
    </visual>
  </link>
  <link name="no40_top_straw">
    <visual>
      <geometry>
        <cylinder length="0.3" radius="0.02"/>
      </geometry>
      <origin rpy="0 0 0" xyz="0 0 0.15"/>
      <material name="green">
        <color rgba="0 1 0 1"/>
      </material>
    </visual>
  </link>
  <joint name="no40_main_joint" type="revolute">
    <parent link="base_link"/>
    <child link="no40_bot_straw"/>
    <origin xyz="-0.0809016994375 0.0587785252292 0"/>
    <axis xyz="0.0587785252292 0.0809016994375 0"/>
    <limit effort="300" lower="-1.5707963268" upper="0" velocity="0.1"/>
    <mimic joint="master_main_joint" multiplier="1.0" offset="0.0"/>
    <dynamics damping="50" friction="1"/>
  </joint>
  <joint name="no40_slave_joint" type="revolute">
    <parent link="no40_bot_straw"/>
    <child link="no40_top_straw"/>
    <origin xyz="0 0 0.3"/>
    <axis xyz="0.0587785252292 0.0809016994375 0"/>
    <limit effort="300" lower="-3.14159265359" upper="3.14159265359" velocity="0.1"/>
    <mimic joint="no40_main_joint" multiplier="-2.0" offset="0.0"/>
    <dynamics damping="50" friction="1"/>
  </joint>
  <link name="no41_bot_straw">
    <visual>
      <geometry>
        <cylinder length="0.3" radius="0.02"/>
      </geometry>
      <origin rpy="0 0 0" xyz="0 0 0.15"/>
      <material name="green">
        <color rgba="0 1 0 1"/>
      </material>
    </visual>
  </link>
  <link name="no41_top_straw">
    <visual>
      <geometry>
        <cylinder length="0.3" radius="0.02"/>
      </geometry>
      <origin rpy="0 0 0" xyz="0 0 0.15"/>
      <material name="green">
        <color rgba="0 1 0 1"/>
      </material>
    </visual>
  </link>
  <joint name="no41_main_joint" type="revolute">
    <parent link="base_link"/>
    <child link="no41_bot_straw"/>
    <origin xyz="-0.0844327925502 0.0535826794979 0"/>
    <axis xyz="0.0535826794979 0.0844327925502 0"/>
    <limit effort="300" lower="-1.5707963268" upper="0" velocity="0.1"/>
    <mimic joint="master_main_joint" multiplier="1.0" offset="0.0"/>
    <dynamics damping="50" friction="1"/>
  </joint>
  <joint name="no41_slave_joint" type="revolute">
    <parent link="no41_bot_straw"/>
    <child link="no41_top_straw"/>
    <origin xyz="0 0 0.3"/>
    <axis xyz="0.0535826794979 0.0844327925502 0"/>
    <limit effort="300" lower="-3.14159265359" upper="3.14159265359" velocity="0.1"/>
    <mimic joint="no41_main_joint" multiplier="-2.0" offset="0.0"/>
    <dynamics damping="50" friction="1"/>
  </joint>
  <link name="no42_bot_straw">
    <visual>
      <geometry>
        <cylinder length="0.3" radius="0.02"/>
      </geometry>
      <origin rpy="0 0 0" xyz="0 0 0.15"/>
      <material name="green">
        <color rgba="0 1 0 1"/>
      </material>
    </visual>
  </link>
  <link name="no42_top_straw">
    <visual>
      <geometry>
        <cylinder length="0.3" radius="0.02"/>
      </geometry>
      <origin rpy="0 0 0" xyz="0 0 0.15"/>
      <material name="green">
        <color rgba="0 1 0 1"/>
      </material>
    </visual>
  </link>
  <joint name="no42_main_joint" type="revolute">
    <parent link="base_link"/>
    <child link="no42_bot_straw"/>
    <origin xyz="-0.0876306680044 0.0481753674102 0"/>
    <axis xyz="0.0481753674102 0.0876306680044 0"/>
    <limit effort="300" lower="-1.5707963268" upper="0" velocity="0.1"/>
    <mimic joint="master_main_joint" multiplier="1.0" offset="0.0"/>
    <dynamics damping="50" friction="1"/>
  </joint>
  <joint name="no42_slave_joint" type="revolute">
    <parent link="no42_bot_straw"/>
    <child link="no42_top_straw"/>
    <origin xyz="0 0 0.3"/>
    <axis xyz="0.0481753674102 0.0876306680044 0"/>
    <limit effort="300" lower="-3.14159265359" upper="3.14159265359" velocity="0.1"/>
    <mimic joint="no42_main_joint" multiplier="-2.0" offset="0.0"/>
    <dynamics damping="50" friction="1"/>
  </joint>
  <link name="no43_bot_straw">
    <visual>
      <geometry>
        <cylinder length="0.3" radius="0.02"/>
      </geometry>
      <origin rpy="0 0 0" xyz="0 0 0.15"/>
      <material name="green">
        <color rgba="0 1 0 1"/>
      </material>
    </visual>
  </link>
  <link name="no43_top_straw">
    <visual>
      <geometry>
        <cylinder length="0.3" radius="0.02"/>
      </geometry>
      <origin rpy="0 0 0" xyz="0 0 0.15"/>
      <material name="green">
        <color rgba="0 1 0 1"/>
      </material>
    </visual>
  </link>
  <joint name="no43_main_joint" type="revolute">
    <parent link="base_link"/>
    <child link="no43_bot_straw"/>
    <origin xyz="-0.0904827052466 0.0425779291565 0"/>
    <axis xyz="0.0425779291565 0.0904827052466 0"/>
    <limit effort="300" lower="-1.5707963268" upper="0" velocity="0.1"/>
    <mimic joint="master_main_joint" multiplier="1.0" offset="0.0"/>
    <dynamics damping="50" friction="1"/>
  </joint>
  <joint name="no43_slave_joint" type="revolute">
    <parent link="no43_bot_straw"/>
    <child link="no43_top_straw"/>
    <origin xyz="0 0 0.3"/>
    <axis xyz="0.0425779291565 0.0904827052466 0"/>
    <limit effort="300" lower="-3.14159265359" upper="3.14159265359" velocity="0.1"/>
    <mimic joint="no43_main_joint" multiplier="-2.0" offset="0.0"/>
    <dynamics damping="50" friction="1"/>
  </joint>
  <link name="no44_bot_straw">
    <visual>
      <geometry>
        <cylinder length="0.3" radius="0.02"/>
      </geometry>
      <origin rpy="0 0 0" xyz="0 0 0.15"/>
      <material name="green">
        <color rgba="0 1 0 1"/>
      </material>
    </visual>
  </link>
  <link name="no44_top_straw">
    <visual>
      <geometry>
        <cylinder length="0.3" radius="0.02"/>
      </geometry>
      <origin rpy="0 0 0" xyz="0 0 0.15"/>
      <material name="green">
        <color rgba="0 1 0 1"/>
      </material>
    </visual>
  </link>
  <joint name="no44_main_joint" type="revolute">
    <parent link="base_link"/>
    <child link="no44_bot_straw"/>
    <origin xyz="-0.0929776485888 0.0368124552685 0"/>
    <axis xyz="0.0368124552685 0.0929776485888 0"/>
    <limit effort="300" lower="-1.5707963268" upper="0" velocity="0.1"/>
    <mimic joint="master_main_joint" multiplier="1.0" offset="0.0"/>
    <dynamics damping="50" friction="1"/>
  </joint>
  <joint name="no44_slave_joint" type="revolute">
    <parent link="no44_bot_straw"/>
    <child link="no44_top_straw"/>
    <origin xyz="0 0 0.3"/>
    <axis xyz="0.0368124552685 0.0929776485888 0"/>
    <limit effort="300" lower="-3.14159265359" upper="3.14159265359" velocity="0.1"/>
    <mimic joint="no44_main_joint" multiplier="-2.0" offset="0.0"/>
    <dynamics damping="50" friction="1"/>
  </joint>
  <link name="no45_bot_straw">
    <visual>
      <geometry>
        <cylinder length="0.3" radius="0.02"/>
      </geometry>
      <origin rpy="0 0 0" xyz="0 0 0.15"/>
      <material name="green">
        <color rgba="0 1 0 1"/>
      </material>
    </visual>
  </link>
  <link name="no45_top_straw">
    <visual>
      <geometry>
        <cylinder length="0.3" radius="0.02"/>
      </geometry>
      <origin rpy="0 0 0" xyz="0 0 0.15"/>
      <material name="green">
        <color rgba="0 1 0 1"/>
      </material>
    </visual>
  </link>
  <joint name="no45_main_joint" type="revolute">
    <parent link="base_link"/>
    <child link="no45_bot_straw"/>
    <origin xyz="-0.0951056516295 0.0309016994375 0"/>
    <axis xyz="0.0309016994375 0.0951056516295 0"/>
    <limit effort="300" lower="-1.5707963268" upper="0" velocity="0.1"/>
    <mimic joint="master_main_joint" multiplier="1.0" offset="0.0"/>
    <dynamics damping="50" friction="1"/>
  </joint>
  <joint name="no45_slave_joint" type="revolute">
    <parent link="no45_bot_straw"/>
    <child link="no45_top_straw"/>
    <origin xyz="0 0 0.3"/>
    <axis xyz="0.0309016994375 0.0951056516295 0"/>
    <limit effort="300" lower="-3.14159265359" upper="3.14159265359" velocity="0.1"/>
    <mimic joint="no45_main_joint" multiplier="-2.0" offset="0.0"/>
    <dynamics damping="50" friction="1"/>
  </joint>
  <link name="no46_bot_straw">
    <visual>
      <geometry>
        <cylinder length="0.3" radius="0.02"/>
      </geometry>
      <origin rpy="0 0 0" xyz="0 0 0.15"/>
      <material name="green">
        <color rgba="0 1 0 1"/>
      </material>
    </visual>
  </link>
  <link name="no46_top_straw">
    <visual>
      <geometry>
        <cylinder length="0.3" radius="0.02"/>
      </geometry>
      <origin rpy="0 0 0" xyz="0 0 0.15"/>
      <material name="green">
        <color rgba="0 1 0 1"/>
      </material>
    </visual>
  </link>
  <joint name="no46_main_joint" type="revolute">
    <parent link="base_link"/>
    <child link="no46_bot_straw"/>
    <origin xyz="-0.0968583161129 0.0248689887165 0"/>
    <axis xyz="0.0248689887165 0.0968583161129 0"/>
    <limit effort="300" lower="-1.5707963268" upper="0" velocity="0.1"/>
    <mimic joint="master_main_joint" multiplier="1.0" offset="0.0"/>
    <dynamics damping="50" friction="1"/>
  </joint>
  <joint name="no46_slave_joint" type="revolute">
    <parent link="no46_bot_straw"/>
    <child link="no46_top_straw"/>
    <origin xyz="0 0 0.3"/>
    <axis xyz="0.0248689887165 0.0968583161129 0"/>
    <limit effort="300" lower="-3.14159265359" upper="3.14159265359" velocity="0.1"/>
    <mimic joint="no46_main_joint" multiplier="-2.0" offset="0.0"/>
    <dynamics damping="50" friction="1"/>
  </joint>
  <link name="no47_bot_straw">
    <visual>
      <geometry>
        <cylinder length="0.3" radius="0.02"/>
      </geometry>
      <origin rpy="0 0 0" xyz="0 0 0.15"/>
      <material name="green">
        <color rgba="0 1 0 1"/>
      </material>
    </visual>
  </link>
  <link name="no47_top_straw">
    <visual>
      <geometry>
        <cylinder length="0.3" radius="0.02"/>
      </geometry>
      <origin rpy="0 0 0" xyz="0 0 0.15"/>
      <material name="green">
        <color rgba="0 1 0 1"/>
      </material>
    </visual>
  </link>
  <joint name="no47_main_joint" type="revolute">
    <parent link="base_link"/>
    <child link="no47_bot_straw"/>
    <origin xyz="-0.0982287250729 0.0187381314586 0"/>
    <axis xyz="0.0187381314586 0.0982287250729 0"/>
    <limit effort="300" lower="-1.5707963268" upper="0" velocity="0.1"/>
    <mimic joint="master_main_joint" multiplier="1.0" offset="0.0"/>
    <dynamics damping="50" friction="1"/>
  </joint>
  <joint name="no47_slave_joint" type="revolute">
    <parent link="no47_bot_straw"/>
    <child link="no47_top_straw"/>
    <origin xyz="0 0 0.3"/>
    <axis xyz="0.0187381314586 0.0982287250729 0"/>
    <limit effort="300" lower="-3.14159265359" upper="3.14159265359" velocity="0.1"/>
    <mimic joint="no47_main_joint" multiplier="-2.0" offset="0.0"/>
    <dynamics damping="50" friction="1"/>
  </joint>
  <link name="no48_bot_straw">
    <visual>
      <geometry>
        <cylinder length="0.3" radius="0.02"/>
      </geometry>
      <origin rpy="0 0 0" xyz="0 0 0.15"/>
      <material name="green">
        <color rgba="0 1 0 1"/>
      </material>
    </visual>
  </link>
  <link name="no48_top_straw">
    <visual>
      <geometry>
        <cylinder length="0.3" radius="0.02"/>
      </geometry>
      <origin rpy="0 0 0" xyz="0 0 0.15"/>
      <material name="green">
        <color rgba="0 1 0 1"/>
      </material>
    </visual>
  </link>
  <joint name="no48_main_joint" type="revolute">
    <parent link="base_link"/>
    <child link="no48_bot_straw"/>
    <origin xyz="-0.0992114701315 0.0125333233564 0"/>
    <axis xyz="0.0125333233564 0.0992114701315 0"/>
    <limit effort="300" lower="-1.5707963268" upper="0" velocity="0.1"/>
    <mimic joint="master_main_joint" multiplier="1.0" offset="0.0"/>
    <dynamics damping="50" friction="1"/>
  </joint>
  <joint name="no48_slave_joint" type="revolute">
    <parent link="no48_bot_straw"/>
    <child link="no48_top_straw"/>
    <origin xyz="0 0 0.3"/>
    <axis xyz="0.0125333233564 0.0992114701315 0"/>
    <limit effort="300" lower="-3.14159265359" upper="3.14159265359" velocity="0.1"/>
    <mimic joint="no48_main_joint" multiplier="-2.0" offset="0.0"/>
    <dynamics damping="50" friction="1"/>
  </joint>
  <link name="no49_bot_straw">
    <visual>
      <geometry>
        <cylinder length="0.3" radius="0.02"/>
      </geometry>
      <origin rpy="0 0 0" xyz="0 0 0.15"/>
      <material name="green">
        <color rgba="0 1 0 1"/>
      </material>
    </visual>
  </link>
  <link name="no49_top_straw">
    <visual>
      <geometry>
        <cylinder length="0.3" radius="0.02"/>
      </geometry>
      <origin rpy="0 0 0" xyz="0 0 0.15"/>
      <material name="green">
        <color rgba="0 1 0 1"/>
      </material>
    </visual>
  </link>
  <joint name="no49_main_joint" type="revolute">
    <parent link="base_link"/>
    <child link="no49_bot_straw"/>
    <origin xyz="-0.0998026728428 0.00627905195291 0"/>
    <axis xyz="0.00627905195291 0.0998026728428 0"/>
    <limit effort="300" lower="-1.5707963268" upper="0" velocity="0.1"/>
    <mimic joint="master_main_joint" multiplier="1.0" offset="0.0"/>
    <dynamics damping="50" friction="1"/>
  </joint>
  <joint name="no49_slave_joint" type="revolute">
    <parent link="no49_bot_straw"/>
    <child link="no49_top_straw"/>
    <origin xyz="0 0 0.3"/>
    <axis xyz="0.00627905195291 0.0998026728428 0"/>
    <limit effort="300" lower="-3.14159265359" upper="3.14159265359" velocity="0.1"/>
    <mimic joint="no49_main_joint" multiplier="-2.0" offset="0.0"/>
    <dynamics damping="50" friction="1"/>
  </joint>
  <link name="no50_bot_straw">
    <visual>
      <geometry>
        <cylinder length="0.3" radius="0.02"/>
      </geometry>
      <origin rpy="0 0 0" xyz="0 0 0.15"/>
      <material name="green">
        <color rgba="0 1 0 1"/>
      </material>
    </visual>
  </link>
  <link name="no50_top_straw">
    <visual>
      <geometry>
        <cylinder length="0.3" radius="0.02"/>
      </geometry>
      <origin rpy="0 0 0" xyz="0 0 0.15"/>
      <material name="green">
        <color rgba="0 1 0 1"/>
      </material>
    </visual>
  </link>
  <joint name="no50_main_joint" type="revolute">
    <parent link="base_link"/>
    <child link="no50_bot_straw"/>
    <origin xyz="-0.1 -2.0682310711e-14 0"/>
    <axis xyz="-2.0682310711e-14 0.1 0"/>
    <limit effort="300" lower="-1.5707963268" upper="0" velocity="0.1"/>
    <mimic joint="master_main_joint" multiplier="1.0" offset="0.0"/>
    <dynamics damping="50" friction="1"/>
  </joint>
  <joint name="no50_slave_joint" type="revolute">
    <parent link="no50_bot_straw"/>
    <child link="no50_top_straw"/>
    <origin xyz="0 0 0.3"/>
    <axis xyz="-2.0682310711e-14 0.1 0"/>
    <limit effort="300" lower="-3.14159265359" upper="3.14159265359" velocity="0.1"/>
    <mimic joint="no50_main_joint" multiplier="-2.0" offset="0.0"/>
    <dynamics damping="50" friction="1"/>
  </joint>
  <link name="no51_bot_straw">
    <visual>
      <geometry>
        <cylinder length="0.3" radius="0.02"/>
      </geometry>
      <origin rpy="0 0 0" xyz="0 0 0.15"/>
      <material name="green">
        <color rgba="0 1 0 1"/>
      </material>
    </visual>
  </link>
  <link name="no51_top_straw">
    <visual>
      <geometry>
        <cylinder length="0.3" radius="0.02"/>
      </geometry>
      <origin rpy="0 0 0" xyz="0 0 0.15"/>
      <material name="green">
        <color rgba="0 1 0 1"/>
      </material>
    </visual>
  </link>
  <joint name="no51_main_joint" type="revolute">
    <parent link="base_link"/>
    <child link="no51_bot_straw"/>
    <origin xyz="-0.0998026728428 -0.00627905195295 0"/>
    <axis xyz="-0.00627905195295 0.0998026728428 0"/>
    <limit effort="300" lower="-1.5707963268" upper="0" velocity="0.1"/>
    <mimic joint="master_main_joint" multiplier="1.0" offset="0.0"/>
    <dynamics damping="50" friction="1"/>
  </joint>
  <joint name="no51_slave_joint" type="revolute">
    <parent link="no51_bot_straw"/>
    <child link="no51_top_straw"/>
    <origin xyz="0 0 0.3"/>
    <axis xyz="-0.00627905195295 0.0998026728428 0"/>
    <limit effort="300" lower="-3.14159265359" upper="3.14159265359" velocity="0.1"/>
    <mimic joint="no51_main_joint" multiplier="-2.0" offset="0.0"/>
    <dynamics damping="50" friction="1"/>
  </joint>
  <link name="no52_bot_straw">
    <visual>
      <geometry>
        <cylinder length="0.3" radius="0.02"/>
      </geometry>
      <origin rpy="0 0 0" xyz="0 0 0.15"/>
      <material name="green">
        <color rgba="0 1 0 1"/>
      </material>
    </visual>
  </link>
  <link name="no52_top_straw">
    <visual>
      <geometry>
        <cylinder length="0.3" radius="0.02"/>
      </geometry>
      <origin rpy="0 0 0" xyz="0 0 0.15"/>
      <material name="green">
        <color rgba="0 1 0 1"/>
      </material>
    </visual>
  </link>
  <joint name="no52_main_joint" type="revolute">
    <parent link="base_link"/>
    <child link="no52_bot_straw"/>
    <origin xyz="-0.0992114701314 -0.0125333233565 0"/>
    <axis xyz="-0.0125333233565 0.0992114701314 0"/>
    <limit effort="300" lower="-1.5707963268" upper="0" velocity="0.1"/>
    <mimic joint="master_main_joint" multiplier="1.0" offset="0.0"/>
    <dynamics damping="50" friction="1"/>
  </joint>
  <joint name="no52_slave_joint" type="revolute">
    <parent link="no52_bot_straw"/>
    <child link="no52_top_straw"/>
    <origin xyz="0 0 0.3"/>
    <axis xyz="-0.0125333233565 0.0992114701314 0"/>
    <limit effort="300" lower="-3.14159265359" upper="3.14159265359" velocity="0.1"/>
    <mimic joint="no52_main_joint" multiplier="-2.0" offset="0.0"/>
    <dynamics damping="50" friction="1"/>
  </joint>
  <link name="no53_bot_straw">
    <visual>
      <geometry>
        <cylinder length="0.3" radius="0.02"/>
      </geometry>
      <origin rpy="0 0 0" xyz="0 0 0.15"/>
      <material name="green">
        <color rgba="0 1 0 1"/>
      </material>
    </visual>
  </link>
  <link name="no53_top_straw">
    <visual>
      <geometry>
        <cylinder length="0.3" radius="0.02"/>
      </geometry>
      <origin rpy="0 0 0" xyz="0 0 0.15"/>
      <material name="green">
        <color rgba="0 1 0 1"/>
      </material>
    </visual>
  </link>
  <joint name="no53_main_joint" type="revolute">
    <parent link="base_link"/>
    <child link="no53_bot_straw"/>
    <origin xyz="-0.0982287250729 -0.0187381314586 0"/>
    <axis xyz="-0.0187381314586 0.0982287250729 0"/>
    <limit effort="300" lower="-1.5707963268" upper="0" velocity="0.1"/>
    <mimic joint="master_main_joint" multiplier="1.0" offset="0.0"/>
    <dynamics damping="50" friction="1"/>
  </joint>
  <joint name="no53_slave_joint" type="revolute">
    <parent link="no53_bot_straw"/>
    <child link="no53_top_straw"/>
    <origin xyz="0 0 0.3"/>
    <axis xyz="-0.0187381314586 0.0982287250729 0"/>
    <limit effort="300" lower="-3.14159265359" upper="3.14159265359" velocity="0.1"/>
    <mimic joint="no53_main_joint" multiplier="-2.0" offset="0.0"/>
    <dynamics damping="50" friction="1"/>
  </joint>
  <link name="no54_bot_straw">
    <visual>
      <geometry>
        <cylinder length="0.3" radius="0.02"/>
      </geometry>
      <origin rpy="0 0 0" xyz="0 0 0.15"/>
      <material name="green">
        <color rgba="0 1 0 1"/>
      </material>
    </visual>
  </link>
  <link name="no54_top_straw">
    <visual>
      <geometry>
        <cylinder length="0.3" radius="0.02"/>
      </geometry>
      <origin rpy="0 0 0" xyz="0 0 0.15"/>
      <material name="green">
        <color rgba="0 1 0 1"/>
      </material>
    </visual>
  </link>
  <joint name="no54_main_joint" type="revolute">
    <parent link="base_link"/>
    <child link="no54_bot_straw"/>
    <origin xyz="-0.0968583161129 -0.0248689887165 0"/>
    <axis xyz="-0.0248689887165 0.0968583161129 0"/>
    <limit effort="300" lower="-1.5707963268" upper="0" velocity="0.1"/>
    <mimic joint="master_main_joint" multiplier="1.0" offset="0.0"/>
    <dynamics damping="50" friction="1"/>
  </joint>
  <joint name="no54_slave_joint" type="revolute">
    <parent link="no54_bot_straw"/>
    <child link="no54_top_straw"/>
    <origin xyz="0 0 0.3"/>
    <axis xyz="-0.0248689887165 0.0968583161129 0"/>
    <limit effort="300" lower="-3.14159265359" upper="3.14159265359" velocity="0.1"/>
    <mimic joint="no54_main_joint" multiplier="-2.0" offset="0.0"/>
    <dynamics damping="50" friction="1"/>
  </joint>
  <link name="no55_bot_straw">
    <visual>
      <geometry>
        <cylinder length="0.3" radius="0.02"/>
      </geometry>
      <origin rpy="0 0 0" xyz="0 0 0.15"/>
      <material name="green">
        <color rgba="0 1 0 1"/>
      </material>
    </visual>
  </link>
  <link name="no55_top_straw">
    <visual>
      <geometry>
        <cylinder length="0.3" radius="0.02"/>
      </geometry>
      <origin rpy="0 0 0" xyz="0 0 0.15"/>
      <material name="green">
        <color rgba="0 1 0 1"/>
      </material>
    </visual>
  </link>
  <joint name="no55_main_joint" type="revolute">
    <parent link="base_link"/>
    <child link="no55_bot_straw"/>
    <origin xyz="-0.0951056516295 -0.0309016994375 0"/>
    <axis xyz="-0.0309016994375 0.0951056516295 0"/>
    <limit effort="300" lower="-1.5707963268" upper="0" velocity="0.1"/>
    <mimic joint="master_main_joint" multiplier="1.0" offset="0.0"/>
    <dynamics damping="50" friction="1"/>
  </joint>
  <joint name="no55_slave_joint" type="revolute">
    <parent link="no55_bot_straw"/>
    <child link="no55_top_straw"/>
    <origin xyz="0 0 0.3"/>
    <axis xyz="-0.0309016994375 0.0951056516295 0"/>
    <limit effort="300" lower="-3.14159265359" upper="3.14159265359" velocity="0.1"/>
    <mimic joint="no55_main_joint" multiplier="-2.0" offset="0.0"/>
    <dynamics damping="50" friction="1"/>
  </joint>
  <link name="no56_bot_straw">
    <visual>
      <geometry>
        <cylinder length="0.3" radius="0.02"/>
      </geometry>
      <origin rpy="0 0 0" xyz="0 0 0.15"/>
      <material name="green">
        <color rgba="0 1 0 1"/>
      </material>
    </visual>
  </link>
  <link name="no56_top_straw">
    <visual>
      <geometry>
        <cylinder length="0.3" radius="0.02"/>
      </geometry>
      <origin rpy="0 0 0" xyz="0 0 0.15"/>
      <material name="green">
        <color rgba="0 1 0 1"/>
      </material>
    </visual>
  </link>
  <joint name="no56_main_joint" type="revolute">
    <parent link="base_link"/>
    <child link="no56_bot_straw"/>
    <origin xyz="-0.0929776485888 -0.0368124552685 0"/>
    <axis xyz="-0.0368124552685 0.0929776485888 0"/>
    <limit effort="300" lower="-1.5707963268" upper="0" velocity="0.1"/>
    <mimic joint="master_main_joint" multiplier="1.0" offset="0.0"/>
    <dynamics damping="50" friction="1"/>
  </joint>
  <joint name="no56_slave_joint" type="revolute">
    <parent link="no56_bot_straw"/>
    <child link="no56_top_straw"/>
    <origin xyz="0 0 0.3"/>
    <axis xyz="-0.0368124552685 0.0929776485888 0"/>
    <limit effort="300" lower="-3.14159265359" upper="3.14159265359" velocity="0.1"/>
    <mimic joint="no56_main_joint" multiplier="-2.0" offset="0.0"/>
    <dynamics damping="50" friction="1"/>
  </joint>
  <link name="no57_bot_straw">
    <visual>
      <geometry>
        <cylinder length="0.3" radius="0.02"/>
      </geometry>
      <origin rpy="0 0 0" xyz="0 0 0.15"/>
      <material name="green">
        <color rgba="0 1 0 1"/>
      </material>
    </visual>
  </link>
  <link name="no57_top_straw">
    <visual>
      <geometry>
        <cylinder length="0.3" radius="0.02"/>
      </geometry>
      <origin rpy="0 0 0" xyz="0 0 0.15"/>
      <material name="green">
        <color rgba="0 1 0 1"/>
      </material>
    </visual>
  </link>
  <joint name="no57_main_joint" type="revolute">
    <parent link="base_link"/>
    <child link="no57_bot_straw"/>
    <origin xyz="-0.0904827052466 -0.0425779291565 0"/>
    <axis xyz="-0.0425779291565 0.0904827052466 0"/>
    <limit effort="300" lower="-1.5707963268" upper="0" velocity="0.1"/>
    <mimic joint="master_main_joint" multiplier="1.0" offset="0.0"/>
    <dynamics damping="50" friction="1"/>
  </joint>
  <joint name="no57_slave_joint" type="revolute">
    <parent link="no57_bot_straw"/>
    <child link="no57_top_straw"/>
    <origin xyz="0 0 0.3"/>
    <axis xyz="-0.0425779291565 0.0904827052466 0"/>
    <limit effort="300" lower="-3.14159265359" upper="3.14159265359" velocity="0.1"/>
    <mimic joint="no57_main_joint" multiplier="-2.0" offset="0.0"/>
    <dynamics damping="50" friction="1"/>
  </joint>
  <link name="no58_bot_straw">
    <visual>
      <geometry>
        <cylinder length="0.3" radius="0.02"/>
      </geometry>
      <origin rpy="0 0 0" xyz="0 0 0.15"/>
      <material name="green">
        <color rgba="0 1 0 1"/>
      </material>
    </visual>
  </link>
  <link name="no58_top_straw">
    <visual>
      <geometry>
        <cylinder length="0.3" radius="0.02"/>
      </geometry>
      <origin rpy="0 0 0" xyz="0 0 0.15"/>
      <material name="green">
        <color rgba="0 1 0 1"/>
      </material>
    </visual>
  </link>
  <joint name="no58_main_joint" type="revolute">
    <parent link="base_link"/>
    <child link="no58_bot_straw"/>
    <origin xyz="-0.0876306680044 -0.0481753674102 0"/>
    <axis xyz="-0.0481753674102 0.0876306680044 0"/>
    <limit effort="300" lower="-1.5707963268" upper="0" velocity="0.1"/>
    <mimic joint="master_main_joint" multiplier="1.0" offset="0.0"/>
    <dynamics damping="50" friction="1"/>
  </joint>
  <joint name="no58_slave_joint" type="revolute">
    <parent link="no58_bot_straw"/>
    <child link="no58_top_straw"/>
    <origin xyz="0 0 0.3"/>
    <axis xyz="-0.0481753674102 0.0876306680044 0"/>
    <limit effort="300" lower="-3.14159265359" upper="3.14159265359" velocity="0.1"/>
    <mimic joint="no58_main_joint" multiplier="-2.0" offset="0.0"/>
    <dynamics damping="50" friction="1"/>
  </joint>
  <link name="no59_bot_straw">
    <visual>
      <geometry>
        <cylinder length="0.3" radius="0.02"/>
      </geometry>
      <origin rpy="0 0 0" xyz="0 0 0.15"/>
      <material name="green">
        <color rgba="0 1 0 1"/>
      </material>
    </visual>
  </link>
  <link name="no59_top_straw">
    <visual>
      <geometry>
        <cylinder length="0.3" radius="0.02"/>
      </geometry>
      <origin rpy="0 0 0" xyz="0 0 0.15"/>
      <material name="green">
        <color rgba="0 1 0 1"/>
      </material>
    </visual>
  </link>
  <joint name="no59_main_joint" type="revolute">
    <parent link="base_link"/>
    <child link="no59_bot_straw"/>
    <origin xyz="-0.0844327925502 -0.0535826794979 0"/>
    <axis xyz="-0.0535826794979 0.0844327925502 0"/>
    <limit effort="300" lower="-1.5707963268" upper="0" velocity="0.1"/>
    <mimic joint="master_main_joint" multiplier="1.0" offset="0.0"/>
    <dynamics damping="50" friction="1"/>
  </joint>
  <joint name="no59_slave_joint" type="revolute">
    <parent link="no59_bot_straw"/>
    <child link="no59_top_straw"/>
    <origin xyz="0 0 0.3"/>
    <axis xyz="-0.0535826794979 0.0844327925502 0"/>
    <limit effort="300" lower="-3.14159265359" upper="3.14159265359" velocity="0.1"/>
    <mimic joint="no59_main_joint" multiplier="-2.0" offset="0.0"/>
    <dynamics damping="50" friction="1"/>
  </joint>
  <link name="no60_bot_straw">
    <visual>
      <geometry>
        <cylinder length="0.3" radius="0.02"/>
      </geometry>
      <origin rpy="0 0 0" xyz="0 0 0.15"/>
      <material name="green">
        <color rgba="0 1 0 1"/>
      </material>
    </visual>
  </link>
  <link name="no60_top_straw">
    <visual>
      <geometry>
        <cylinder length="0.3" radius="0.02"/>
      </geometry>
      <origin rpy="0 0 0" xyz="0 0 0.15"/>
      <material name="green">
        <color rgba="0 1 0 1"/>
      </material>
    </visual>
  </link>
  <joint name="no60_main_joint" type="revolute">
    <parent link="base_link"/>
    <child link="no60_bot_straw"/>
    <origin xyz="-0.0809016994375 -0.0587785252293 0"/>
    <axis xyz="-0.0587785252293 0.0809016994375 0"/>
    <limit effort="300" lower="-1.5707963268" upper="0" velocity="0.1"/>
    <mimic joint="master_main_joint" multiplier="1.0" offset="0.0"/>
    <dynamics damping="50" friction="1"/>
  </joint>
  <joint name="no60_slave_joint" type="revolute">
    <parent link="no60_bot_straw"/>
    <child link="no60_top_straw"/>
    <origin xyz="0 0 0.3"/>
    <axis xyz="-0.0587785252293 0.0809016994375 0"/>
    <limit effort="300" lower="-3.14159265359" upper="3.14159265359" velocity="0.1"/>
    <mimic joint="no60_main_joint" multiplier="-2.0" offset="0.0"/>
    <dynamics damping="50" friction="1"/>
  </joint>
  <link name="no61_bot_straw">
    <visual>
      <geometry>
        <cylinder length="0.3" radius="0.02"/>
      </geometry>
      <origin rpy="0 0 0" xyz="0 0 0.15"/>
      <material name="green">
        <color rgba="0 1 0 1"/>
      </material>
    </visual>
  </link>
  <link name="no61_top_straw">
    <visual>
      <geometry>
        <cylinder length="0.3" radius="0.02"/>
      </geometry>
      <origin rpy="0 0 0" xyz="0 0 0.15"/>
      <material name="green">
        <color rgba="0 1 0 1"/>
      </material>
    </visual>
  </link>
  <joint name="no61_main_joint" type="revolute">
    <parent link="base_link"/>
    <child link="no61_bot_straw"/>
    <origin xyz="-0.0770513242776 -0.0637423989749 0"/>
    <axis xyz="-0.0637423989749 0.0770513242776 0"/>
    <limit effort="300" lower="-1.5707963268" upper="0" velocity="0.1"/>
    <mimic joint="master_main_joint" multiplier="1.0" offset="0.0"/>
    <dynamics damping="50" friction="1"/>
  </joint>
  <joint name="no61_slave_joint" type="revolute">
    <parent link="no61_bot_straw"/>
    <child link="no61_top_straw"/>
    <origin xyz="0 0 0.3"/>
    <axis xyz="-0.0637423989749 0.0770513242776 0"/>
    <limit effort="300" lower="-3.14159265359" upper="3.14159265359" velocity="0.1"/>
    <mimic joint="no61_main_joint" multiplier="-2.0" offset="0.0"/>
    <dynamics damping="50" friction="1"/>
  </joint>
  <link name="no62_bot_straw">
    <visual>
      <geometry>
        <cylinder length="0.3" radius="0.02"/>
      </geometry>
      <origin rpy="0 0 0" xyz="0 0 0.15"/>
      <material name="green">
        <color rgba="0 1 0 1"/>
      </material>
    </visual>
  </link>
  <link name="no62_top_straw">
    <visual>
      <geometry>
        <cylinder length="0.3" radius="0.02"/>
      </geometry>
      <origin rpy="0 0 0" xyz="0 0 0.15"/>
      <material name="green">
        <color rgba="0 1 0 1"/>
      </material>
    </visual>
  </link>
  <joint name="no62_main_joint" type="revolute">
    <parent link="base_link"/>
    <child link="no62_bot_straw"/>
    <origin xyz="-0.0728968627421 -0.0684547105929 0"/>
    <axis xyz="-0.0684547105929 0.0728968627421 0"/>
    <limit effort="300" lower="-1.5707963268" upper="0" velocity="0.1"/>
    <mimic joint="master_main_joint" multiplier="1.0" offset="0.0"/>
    <dynamics damping="50" friction="1"/>
  </joint>
  <joint name="no62_slave_joint" type="revolute">
    <parent link="no62_bot_straw"/>
    <child link="no62_top_straw"/>
    <origin xyz="0 0 0.3"/>
    <axis xyz="-0.0684547105929 0.0728968627421 0"/>
    <limit effort="300" lower="-3.14159265359" upper="3.14159265359" velocity="0.1"/>
    <mimic joint="no62_main_joint" multiplier="-2.0" offset="0.0"/>
    <dynamics damping="50" friction="1"/>
  </joint>
  <link name="no63_bot_straw">
    <visual>
      <geometry>
        <cylinder length="0.3" radius="0.02"/>
      </geometry>
      <origin rpy="0 0 0" xyz="0 0 0.15"/>
      <material name="green">
        <color rgba="0 1 0 1"/>
      </material>
    </visual>
  </link>
  <link name="no63_top_straw">
    <visual>
      <geometry>
        <cylinder length="0.3" radius="0.02"/>
      </geometry>
      <origin rpy="0 0 0" xyz="0 0 0.15"/>
      <material name="green">
        <color rgba="0 1 0 1"/>
      </material>
    </visual>
  </link>
  <joint name="no63_main_joint" type="revolute">
    <parent link="base_link"/>
    <child link="no63_bot_straw"/>
    <origin xyz="-0.0684547105928 -0.0728968627422 0"/>
    <axis xyz="-0.0728968627422 0.0684547105928 0"/>
    <limit effort="300" lower="-1.5707963268" upper="0" velocity="0.1"/>
    <mimic joint="master_main_joint" multiplier="1.0" offset="0.0"/>
    <dynamics damping="50" friction="1"/>
  </joint>
  <joint name="no63_slave_joint" type="revolute">
    <parent link="no63_bot_straw"/>
    <child link="no63_top_straw"/>
    <origin xyz="0 0 0.3"/>
    <axis xyz="-0.0728968627422 0.0684547105928 0"/>
    <limit effort="300" lower="-3.14159265359" upper="3.14159265359" velocity="0.1"/>
    <mimic joint="no63_main_joint" multiplier="-2.0" offset="0.0"/>
    <dynamics damping="50" friction="1"/>
  </joint>
  <link name="no64_bot_straw">
    <visual>
      <geometry>
        <cylinder length="0.3" radius="0.02"/>
      </geometry>
      <origin rpy="0 0 0" xyz="0 0 0.15"/>
      <material name="green">
        <color rgba="0 1 0 1"/>
      </material>
    </visual>
  </link>
  <link name="no64_top_straw">
    <visual>
      <geometry>
        <cylinder length="0.3" radius="0.02"/>
      </geometry>
      <origin rpy="0 0 0" xyz="0 0 0.15"/>
      <material name="green">
        <color rgba="0 1 0 1"/>
      </material>
    </visual>
  </link>
  <joint name="no64_main_joint" type="revolute">
    <parent link="base_link"/>
    <child link="no64_bot_straw"/>
    <origin xyz="-0.0637423989748 -0.0770513242776 0"/>
    <axis xyz="-0.0770513242776 0.0637423989748 0"/>
    <limit effort="300" lower="-1.5707963268" upper="0" velocity="0.1"/>
    <mimic joint="master_main_joint" multiplier="1.0" offset="0.0"/>
    <dynamics damping="50" friction="1"/>
  </joint>
  <joint name="no64_slave_joint" type="revolute">
    <parent link="no64_bot_straw"/>
    <child link="no64_top_straw"/>
    <origin xyz="0 0 0.3"/>
    <axis xyz="-0.0770513242776 0.0637423989748 0"/>
    <limit effort="300" lower="-3.14159265359" upper="3.14159265359" velocity="0.1"/>
    <mimic joint="no64_main_joint" multiplier="-2.0" offset="0.0"/>
    <dynamics damping="50" friction="1"/>
  </joint>
  <link name="no65_bot_straw">
    <visual>
      <geometry>
        <cylinder length="0.3" radius="0.02"/>
      </geometry>
      <origin rpy="0 0 0" xyz="0 0 0.15"/>
      <material name="green">
        <color rgba="0 1 0 1"/>
      </material>
    </visual>
  </link>
  <link name="no65_top_straw">
    <visual>
      <geometry>
        <cylinder length="0.3" radius="0.02"/>
      </geometry>
      <origin rpy="0 0 0" xyz="0 0 0.15"/>
      <material name="green">
        <color rgba="0 1 0 1"/>
      </material>
    </visual>
  </link>
  <joint name="no65_main_joint" type="revolute">
    <parent link="base_link"/>
    <child link="no65_bot_straw"/>
    <origin xyz="-0.0587785252292 -0.0809016994375 0"/>
    <axis xyz="-0.0809016994375 0.0587785252292 0"/>
    <limit effort="300" lower="-1.5707963268" upper="0" velocity="0.1"/>
    <mimic joint="master_main_joint" multiplier="1.0" offset="0.0"/>
    <dynamics damping="50" friction="1"/>
  </joint>
  <joint name="no65_slave_joint" type="revolute">
    <parent link="no65_bot_straw"/>
    <child link="no65_top_straw"/>
    <origin xyz="0 0 0.3"/>
    <axis xyz="-0.0809016994375 0.0587785252292 0"/>
    <limit effort="300" lower="-3.14159265359" upper="3.14159265359" velocity="0.1"/>
    <mimic joint="no65_main_joint" multiplier="-2.0" offset="0.0"/>
    <dynamics damping="50" friction="1"/>
  </joint>
  <link name="no66_bot_straw">
    <visual>
      <geometry>
        <cylinder length="0.3" radius="0.02"/>
      </geometry>
      <origin rpy="0 0 0" xyz="0 0 0.15"/>
      <material name="green">
        <color rgba="0 1 0 1"/>
      </material>
    </visual>
  </link>
  <link name="no66_top_straw">
    <visual>
      <geometry>
        <cylinder length="0.3" radius="0.02"/>
      </geometry>
      <origin rpy="0 0 0" xyz="0 0 0.15"/>
      <material name="green">
        <color rgba="0 1 0 1"/>
      </material>
    </visual>
  </link>
  <joint name="no66_main_joint" type="revolute">
    <parent link="base_link"/>
    <child link="no66_bot_straw"/>
    <origin xyz="-0.0535826794979 -0.0844327925502 0"/>
    <axis xyz="-0.0844327925502 0.0535826794979 0"/>
    <limit effort="300" lower="-1.5707963268" upper="0" velocity="0.1"/>
    <mimic joint="master_main_joint" multiplier="1.0" offset="0.0"/>
    <dynamics damping="50" friction="1"/>
  </joint>
  <joint name="no66_slave_joint" type="revolute">
    <parent link="no66_bot_straw"/>
    <child link="no66_top_straw"/>
    <origin xyz="0 0 0.3"/>
    <axis xyz="-0.0844327925502 0.0535826794979 0"/>
    <limit effort="300" lower="-3.14159265359" upper="3.14159265359" velocity="0.1"/>
    <mimic joint="no66_main_joint" multiplier="-2.0" offset="0.0"/>
    <dynamics damping="50" friction="1"/>
  </joint>
  <link name="no67_bot_straw">
    <visual>
      <geometry>
        <cylinder length="0.3" radius="0.02"/>
      </geometry>
      <origin rpy="0 0 0" xyz="0 0 0.15"/>
      <material name="green">
        <color rgba="0 1 0 1"/>
      </material>
    </visual>
  </link>
  <link name="no67_top_straw">
    <visual>
      <geometry>
        <cylinder length="0.3" radius="0.02"/>
      </geometry>
      <origin rpy="0 0 0" xyz="0 0 0.15"/>
      <material name="green">
        <color rgba="0 1 0 1"/>
      </material>
    </visual>
  </link>
  <joint name="no67_main_joint" type="revolute">
    <parent link="base_link"/>
    <child link="no67_bot_straw"/>
    <origin xyz="-0.0481753674101 -0.0876306680044 0"/>
    <axis xyz="-0.0876306680044 0.0481753674101 0"/>
    <limit effort="300" lower="-1.5707963268" upper="0" velocity="0.1"/>
    <mimic joint="master_main_joint" multiplier="1.0" offset="0.0"/>
    <dynamics damping="50" friction="1"/>
  </joint>
  <joint name="no67_slave_joint" type="revolute">
    <parent link="no67_bot_straw"/>
    <child link="no67_top_straw"/>
    <origin xyz="0 0 0.3"/>
    <axis xyz="-0.0876306680044 0.0481753674101 0"/>
    <limit effort="300" lower="-3.14159265359" upper="3.14159265359" velocity="0.1"/>
    <mimic joint="no67_main_joint" multiplier="-2.0" offset="0.0"/>
    <dynamics damping="50" friction="1"/>
  </joint>
  <link name="no68_bot_straw">
    <visual>
      <geometry>
        <cylinder length="0.3" radius="0.02"/>
      </geometry>
      <origin rpy="0 0 0" xyz="0 0 0.15"/>
      <material name="green">
        <color rgba="0 1 0 1"/>
      </material>
    </visual>
  </link>
  <link name="no68_top_straw">
    <visual>
      <geometry>
        <cylinder length="0.3" radius="0.02"/>
      </geometry>
      <origin rpy="0 0 0" xyz="0 0 0.15"/>
      <material name="green">
        <color rgba="0 1 0 1"/>
      </material>
    </visual>
  </link>
  <joint name="no68_main_joint" type="revolute">
    <parent link="base_link"/>
    <child link="no68_bot_straw"/>
    <origin xyz="-0.0425779291565 -0.0904827052466 0"/>
    <axis xyz="-0.0904827052466 0.0425779291565 0"/>
    <limit effort="300" lower="-1.5707963268" upper="0" velocity="0.1"/>
    <mimic joint="master_main_joint" multiplier="1.0" offset="0.0"/>
    <dynamics damping="50" friction="1"/>
  </joint>
  <joint name="no68_slave_joint" type="revolute">
    <parent link="no68_bot_straw"/>
    <child link="no68_top_straw"/>
    <origin xyz="0 0 0.3"/>
    <axis xyz="-0.0904827052466 0.0425779291565 0"/>
    <limit effort="300" lower="-3.14159265359" upper="3.14159265359" velocity="0.1"/>
    <mimic joint="no68_main_joint" multiplier="-2.0" offset="0.0"/>
    <dynamics damping="50" friction="1"/>
  </joint>
  <link name="no69_bot_straw">
    <visual>
      <geometry>
        <cylinder length="0.3" radius="0.02"/>
      </geometry>
      <origin rpy="0 0 0" xyz="0 0 0.15"/>
      <material name="green">
        <color rgba="0 1 0 1"/>
      </material>
    </visual>
  </link>
  <link name="no69_top_straw">
    <visual>
      <geometry>
        <cylinder length="0.3" radius="0.02"/>
      </geometry>
      <origin rpy="0 0 0" xyz="0 0 0.15"/>
      <material name="green">
        <color rgba="0 1 0 1"/>
      </material>
    </visual>
  </link>
  <joint name="no69_main_joint" type="revolute">
    <parent link="base_link"/>
    <child link="no69_bot_straw"/>
    <origin xyz="-0.0368124552684 -0.0929776485888 0"/>
    <axis xyz="-0.0929776485888 0.0368124552684 0"/>
    <limit effort="300" lower="-1.5707963268" upper="0" velocity="0.1"/>
    <mimic joint="master_main_joint" multiplier="1.0" offset="0.0"/>
    <dynamics damping="50" friction="1"/>
  </joint>
  <joint name="no69_slave_joint" type="revolute">
    <parent link="no69_bot_straw"/>
    <child link="no69_top_straw"/>
    <origin xyz="0 0 0.3"/>
    <axis xyz="-0.0929776485888 0.0368124552684 0"/>
    <limit effort="300" lower="-3.14159265359" upper="3.14159265359" velocity="0.1"/>
    <mimic joint="no69_main_joint" multiplier="-2.0" offset="0.0"/>
    <dynamics damping="50" friction="1"/>
  </joint>
  <link name="no70_bot_straw">
    <visual>
      <geometry>
        <cylinder length="0.3" radius="0.02"/>
      </geometry>
      <origin rpy="0 0 0" xyz="0 0 0.15"/>
      <material name="green">
        <color rgba="0 1 0 1"/>
      </material>
    </visual>
  </link>
  <link name="no70_top_straw">
    <visual>
      <geometry>
        <cylinder length="0.3" radius="0.02"/>
      </geometry>
      <origin rpy="0 0 0" xyz="0 0 0.15"/>
      <material name="green">
        <color rgba="0 1 0 1"/>
      </material>
    </visual>
  </link>
  <joint name="no70_main_joint" type="revolute">
    <parent link="base_link"/>
    <child link="no70_bot_straw"/>
    <origin xyz="-0.0309016994375 -0.0951056516295 0"/>
    <axis xyz="-0.0951056516295 0.0309016994375 0"/>
    <limit effort="300" lower="-1.5707963268" upper="0" velocity="0.1"/>
    <mimic joint="master_main_joint" multiplier="1.0" offset="0.0"/>
    <dynamics damping="50" friction="1"/>
  </joint>
  <joint name="no70_slave_joint" type="revolute">
    <parent link="no70_bot_straw"/>
    <child link="no70_top_straw"/>
    <origin xyz="0 0 0.3"/>
    <axis xyz="-0.0951056516295 0.0309016994375 0"/>
    <limit effort="300" lower="-3.14159265359" upper="3.14159265359" velocity="0.1"/>
    <mimic joint="no70_main_joint" multiplier="-2.0" offset="0.0"/>
    <dynamics damping="50" friction="1"/>
  </joint>
  <link name="no71_bot_straw">
    <visual>
      <geometry>
        <cylinder length="0.3" radius="0.02"/>
      </geometry>
      <origin rpy="0 0 0" xyz="0 0 0.15"/>
      <material name="green">
        <color rgba="0 1 0 1"/>
      </material>
    </visual>
  </link>
  <link name="no71_top_straw">
    <visual>
      <geometry>
        <cylinder length="0.3" radius="0.02"/>
      </geometry>
      <origin rpy="0 0 0" xyz="0 0 0.15"/>
      <material name="green">
        <color rgba="0 1 0 1"/>
      </material>
    </visual>
  </link>
  <joint name="no71_main_joint" type="revolute">
    <parent link="base_link"/>
    <child link="no71_bot_straw"/>
    <origin xyz="-0.0248689887165 -0.0968583161129 0"/>
    <axis xyz="-0.0968583161129 0.0248689887165 0"/>
    <limit effort="300" lower="-1.5707963268" upper="0" velocity="0.1"/>
    <mimic joint="master_main_joint" multiplier="1.0" offset="0.0"/>
    <dynamics damping="50" friction="1"/>
  </joint>
  <joint name="no71_slave_joint" type="revolute">
    <parent link="no71_bot_straw"/>
    <child link="no71_top_straw"/>
    <origin xyz="0 0 0.3"/>
    <axis xyz="-0.0968583161129 0.0248689887165 0"/>
    <limit effort="300" lower="-3.14159265359" upper="3.14159265359" velocity="0.1"/>
    <mimic joint="no71_main_joint" multiplier="-2.0" offset="0.0"/>
    <dynamics damping="50" friction="1"/>
  </joint>
  <link name="no72_bot_straw">
    <visual>
      <geometry>
        <cylinder length="0.3" radius="0.02"/>
      </geometry>
      <origin rpy="0 0 0" xyz="0 0 0.15"/>
      <material name="green">
        <color rgba="0 1 0 1"/>
      </material>
    </visual>
  </link>
  <link name="no72_top_straw">
    <visual>
      <geometry>
        <cylinder length="0.3" radius="0.02"/>
      </geometry>
      <origin rpy="0 0 0" xyz="0 0 0.15"/>
      <material name="green">
        <color rgba="0 1 0 1"/>
      </material>
    </visual>
  </link>
  <joint name="no72_main_joint" type="revolute">
    <parent link="base_link"/>
    <child link="no72_bot_straw"/>
    <origin xyz="-0.0187381314585 -0.0982287250729 0"/>
    <axis xyz="-0.0982287250729 0.0187381314585 0"/>
    <limit effort="300" lower="-1.5707963268" upper="0" velocity="0.1"/>
    <mimic joint="master_main_joint" multiplier="1.0" offset="0.0"/>
    <dynamics damping="50" friction="1"/>
  </joint>
  <joint name="no72_slave_joint" type="revolute">
    <parent link="no72_bot_straw"/>
    <child link="no72_top_straw"/>
    <origin xyz="0 0 0.3"/>
    <axis xyz="-0.0982287250729 0.0187381314585 0"/>
    <limit effort="300" lower="-3.14159265359" upper="3.14159265359" velocity="0.1"/>
    <mimic joint="no72_main_joint" multiplier="-2.0" offset="0.0"/>
    <dynamics damping="50" friction="1"/>
  </joint>
  <link name="no73_bot_straw">
    <visual>
      <geometry>
        <cylinder length="0.3" radius="0.02"/>
      </geometry>
      <origin rpy="0 0 0" xyz="0 0 0.15"/>
      <material name="green">
        <color rgba="0 1 0 1"/>
      </material>
    </visual>
  </link>
  <link name="no73_top_straw">
    <visual>
      <geometry>
        <cylinder length="0.3" radius="0.02"/>
      </geometry>
      <origin rpy="0 0 0" xyz="0 0 0.15"/>
      <material name="green">
        <color rgba="0 1 0 1"/>
      </material>
    </visual>
  </link>
  <joint name="no73_main_joint" type="revolute">
    <parent link="base_link"/>
    <child link="no73_bot_straw"/>
    <origin xyz="-0.0125333233564 -0.0992114701315 0"/>
    <axis xyz="-0.0992114701315 0.0125333233564 0"/>
    <limit effort="300" lower="-1.5707963268" upper="0" velocity="0.1"/>
    <mimic joint="master_main_joint" multiplier="1.0" offset="0.0"/>
    <dynamics damping="50" friction="1"/>
  </joint>
  <joint name="no73_slave_joint" type="revolute">
    <parent link="no73_bot_straw"/>
    <child link="no73_top_straw"/>
    <origin xyz="0 0 0.3"/>
    <axis xyz="-0.0992114701315 0.0125333233564 0"/>
    <limit effort="300" lower="-3.14159265359" upper="3.14159265359" velocity="0.1"/>
    <mimic joint="no73_main_joint" multiplier="-2.0" offset="0.0"/>
    <dynamics damping="50" friction="1"/>
  </joint>
  <link name="no74_bot_straw">
    <visual>
      <geometry>
        <cylinder length="0.3" radius="0.02"/>
      </geometry>
      <origin rpy="0 0 0" xyz="0 0 0.15"/>
      <material name="green">
        <color rgba="0 1 0 1"/>
      </material>
    </visual>
  </link>
  <link name="no74_top_straw">
    <visual>
      <geometry>
        <cylinder length="0.3" radius="0.02"/>
      </geometry>
      <origin rpy="0 0 0" xyz="0 0 0.15"/>
      <material name="green">
        <color rgba="0 1 0 1"/>
      </material>
    </visual>
  </link>
  <joint name="no74_main_joint" type="revolute">
    <parent link="base_link"/>
    <child link="no74_bot_straw"/>
    <origin xyz="-0.0062790519529 -0.0998026728428 0"/>
    <axis xyz="-0.0998026728428 0.0062790519529 0"/>
    <limit effort="300" lower="-1.5707963268" upper="0" velocity="0.1"/>
    <mimic joint="master_main_joint" multiplier="1.0" offset="0.0"/>
    <dynamics damping="50" friction="1"/>
  </joint>
  <joint name="no74_slave_joint" type="revolute">
    <parent link="no74_bot_straw"/>
    <child link="no74_top_straw"/>
    <origin xyz="0 0 0.3"/>
    <axis xyz="-0.0998026728428 0.0062790519529 0"/>
    <limit effort="300" lower="-3.14159265359" upper="3.14159265359" velocity="0.1"/>
    <mimic joint="no74_main_joint" multiplier="-2.0" offset="0.0"/>
    <dynamics damping="50" friction="1"/>
  </joint>
  <link name="no75_bot_straw">
    <visual>
      <geometry>
        <cylinder length="0.3" radius="0.02"/>
      </geometry>
      <origin rpy="0 0 0" xyz="0 0 0.15"/>
      <material name="green">
        <color rgba="0 1 0 1"/>
      </material>
    </visual>
  </link>
  <link name="no75_top_straw">
    <visual>
      <geometry>
        <cylinder length="0.3" radius="0.02"/>
      </geometry>
      <origin rpy="0 0 0" xyz="0 0 0.15"/>
      <material name="green">
        <color rgba="0 1 0 1"/>
      </material>
    </visual>
  </link>
  <joint name="no75_main_joint" type="revolute">
    <parent link="base_link"/>
    <child link="no75_bot_straw"/>
    <origin xyz="3.09790571455e-14 -0.1 0"/>
    <axis xyz="-0.1 -3.09790571455e-14 0"/>
    <limit effort="300" lower="-1.5707963268" upper="0" velocity="0.1"/>
    <mimic joint="master_main_joint" multiplier="1.0" offset="0.0"/>
    <dynamics damping="50" friction="1"/>
  </joint>
  <joint name="no75_slave_joint" type="revolute">
    <parent link="no75_bot_straw"/>
    <child link="no75_top_straw"/>
    <origin xyz="0 0 0.3"/>
    <axis xyz="-0.1 -3.09790571455e-14 0"/>
    <limit effort="300" lower="-3.14159265359" upper="3.14159265359" velocity="0.1"/>
    <mimic joint="no75_main_joint" multiplier="-2.0" offset="0.0"/>
    <dynamics damping="50" friction="1"/>
  </joint>
  <link name="no76_bot_straw">
    <visual>
      <geometry>
        <cylinder length="0.3" radius="0.02"/>
      </geometry>
      <origin rpy="0 0 0" xyz="0 0 0.15"/>
      <material name="green">
        <color rgba="0 1 0 1"/>
      </material>
    </visual>
  </link>
  <link name="no76_top_straw">
    <visual>
      <geometry>
        <cylinder length="0.3" radius="0.02"/>
      </geometry>
      <origin rpy="0 0 0" xyz="0 0 0.15"/>
      <material name="green">
        <color rgba="0 1 0 1"/>
      </material>
    </visual>
  </link>
  <joint name="no76_main_joint" type="revolute">
    <parent link="base_link"/>
    <child link="no76_bot_straw"/>
    <origin xyz="0.00627905195296 -0.0998026728428 0"/>
    <axis xyz="-0.0998026728428 -0.00627905195296 0"/>
    <limit effort="300" lower="-1.5707963268" upper="0" velocity="0.1"/>
    <mimic joint="master_main_joint" multiplier="1.0" offset="0.0"/>
    <dynamics damping="50" friction="1"/>
  </joint>
  <joint name="no76_slave_joint" type="revolute">
    <parent link="no76_bot_straw"/>
    <child link="no76_top_straw"/>
    <origin xyz="0 0 0.3"/>
    <axis xyz="-0.0998026728428 -0.00627905195296 0"/>
    <limit effort="300" lower="-3.14159265359" upper="3.14159265359" velocity="0.1"/>
    <mimic joint="no76_main_joint" multiplier="-2.0" offset="0.0"/>
    <dynamics damping="50" friction="1"/>
  </joint>
  <link name="no77_bot_straw">
    <visual>
      <geometry>
        <cylinder length="0.3" radius="0.02"/>
      </geometry>
      <origin rpy="0 0 0" xyz="0 0 0.15"/>
      <material name="green">
        <color rgba="0 1 0 1"/>
      </material>
    </visual>
  </link>
  <link name="no77_top_straw">
    <visual>
      <geometry>
        <cylinder length="0.3" radius="0.02"/>
      </geometry>
      <origin rpy="0 0 0" xyz="0 0 0.15"/>
      <material name="green">
        <color rgba="0 1 0 1"/>
      </material>
    </visual>
  </link>
  <joint name="no77_main_joint" type="revolute">
    <parent link="base_link"/>
    <child link="no77_bot_straw"/>
    <origin xyz="0.0125333233565 -0.0992114701314 0"/>
    <axis xyz="-0.0992114701314 -0.0125333233565 0"/>
    <limit effort="300" lower="-1.5707963268" upper="0" velocity="0.1"/>
    <mimic joint="master_main_joint" multiplier="1.0" offset="0.0"/>
    <dynamics damping="50" friction="1"/>
  </joint>
  <joint name="no77_slave_joint" type="revolute">
    <parent link="no77_bot_straw"/>
    <child link="no77_top_straw"/>
    <origin xyz="0 0 0.3"/>
    <axis xyz="-0.0992114701314 -0.0125333233565 0"/>
    <limit effort="300" lower="-3.14159265359" upper="3.14159265359" velocity="0.1"/>
    <mimic joint="no77_main_joint" multiplier="-2.0" offset="0.0"/>
    <dynamics damping="50" friction="1"/>
  </joint>
  <link name="no78_bot_straw">
    <visual>
      <geometry>
        <cylinder length="0.3" radius="0.02"/>
      </geometry>
      <origin rpy="0 0 0" xyz="0 0 0.15"/>
      <material name="green">
        <color rgba="0 1 0 1"/>
      </material>
    </visual>
  </link>
  <link name="no78_top_straw">
    <visual>
      <geometry>
        <cylinder length="0.3" radius="0.02"/>
      </geometry>
      <origin rpy="0 0 0" xyz="0 0 0.15"/>
      <material name="green">
        <color rgba="0 1 0 1"/>
      </material>
    </visual>
  </link>
  <joint name="no78_main_joint" type="revolute">
    <parent link="base_link"/>
    <child link="no78_bot_straw"/>
    <origin xyz="0.0187381314586 -0.0982287250729 0"/>
    <axis xyz="-0.0982287250729 -0.0187381314586 0"/>
    <limit effort="300" lower="-1.5707963268" upper="0" velocity="0.1"/>
    <mimic joint="master_main_joint" multiplier="1.0" offset="0.0"/>
    <dynamics damping="50" friction="1"/>
  </joint>
  <joint name="no78_slave_joint" type="revolute">
    <parent link="no78_bot_straw"/>
    <child link="no78_top_straw"/>
    <origin xyz="0 0 0.3"/>
    <axis xyz="-0.0982287250729 -0.0187381314586 0"/>
    <limit effort="300" lower="-3.14159265359" upper="3.14159265359" velocity="0.1"/>
    <mimic joint="no78_main_joint" multiplier="-2.0" offset="0.0"/>
    <dynamics damping="50" friction="1"/>
  </joint>
  <link name="no79_bot_straw">
    <visual>
      <geometry>
        <cylinder length="0.3" radius="0.02"/>
      </geometry>
      <origin rpy="0 0 0" xyz="0 0 0.15"/>
      <material name="green">
        <color rgba="0 1 0 1"/>
      </material>
    </visual>
  </link>
  <link name="no79_top_straw">
    <visual>
      <geometry>
        <cylinder length="0.3" radius="0.02"/>
      </geometry>
      <origin rpy="0 0 0" xyz="0 0 0.15"/>
      <material name="green">
        <color rgba="0 1 0 1"/>
      </material>
    </visual>
  </link>
  <joint name="no79_main_joint" type="revolute">
    <parent link="base_link"/>
    <child link="no79_bot_straw"/>
    <origin xyz="0.0248689887165 -0.0968583161129 0"/>
    <axis xyz="-0.0968583161129 -0.0248689887165 0"/>
    <limit effort="300" lower="-1.5707963268" upper="0" velocity="0.1"/>
    <mimic joint="master_main_joint" multiplier="1.0" offset="0.0"/>
    <dynamics damping="50" friction="1"/>
  </joint>
  <joint name="no79_slave_joint" type="revolute">
    <parent link="no79_bot_straw"/>
    <child link="no79_top_straw"/>
    <origin xyz="0 0 0.3"/>
    <axis xyz="-0.0968583161129 -0.0248689887165 0"/>
    <limit effort="300" lower="-3.14159265359" upper="3.14159265359" velocity="0.1"/>
    <mimic joint="no79_main_joint" multiplier="-2.0" offset="0.0"/>
    <dynamics damping="50" friction="1"/>
  </joint>
  <link name="no80_bot_straw">
    <visual>
      <geometry>
        <cylinder length="0.3" radius="0.02"/>
      </geometry>
      <origin rpy="0 0 0" xyz="0 0 0.15"/>
      <material name="green">
        <color rgba="0 1 0 1"/>
      </material>
    </visual>
  </link>
  <link name="no80_top_straw">
    <visual>
      <geometry>
        <cylinder length="0.3" radius="0.02"/>
      </geometry>
      <origin rpy="0 0 0" xyz="0 0 0.15"/>
      <material name="green">
        <color rgba="0 1 0 1"/>
      </material>
    </visual>
  </link>
  <joint name="no80_main_joint" type="revolute">
    <parent link="base_link"/>
    <child link="no80_bot_straw"/>
    <origin xyz="0.0309016994375 -0.0951056516295 0"/>
    <axis xyz="-0.0951056516295 -0.0309016994375 0"/>
    <limit effort="300" lower="-1.5707963268" upper="0" velocity="0.1"/>
    <mimic joint="master_main_joint" multiplier="1.0" offset="0.0"/>
    <dynamics damping="50" friction="1"/>
  </joint>
  <joint name="no80_slave_joint" type="revolute">
    <parent link="no80_bot_straw"/>
    <child link="no80_top_straw"/>
    <origin xyz="0 0 0.3"/>
    <axis xyz="-0.0951056516295 -0.0309016994375 0"/>
    <limit effort="300" lower="-3.14159265359" upper="3.14159265359" velocity="0.1"/>
    <mimic joint="no80_main_joint" multiplier="-2.0" offset="0.0"/>
    <dynamics damping="50" friction="1"/>
  </joint>
  <link name="no81_bot_straw">
    <visual>
      <geometry>
        <cylinder length="0.3" radius="0.02"/>
      </geometry>
      <origin rpy="0 0 0" xyz="0 0 0.15"/>
      <material name="green">
        <color rgba="0 1 0 1"/>
      </material>
    </visual>
  </link>
  <link name="no81_top_straw">
    <visual>
      <geometry>
        <cylinder length="0.3" radius="0.02"/>
      </geometry>
      <origin rpy="0 0 0" xyz="0 0 0.15"/>
      <material name="green">
        <color rgba="0 1 0 1"/>
      </material>
    </visual>
  </link>
  <joint name="no81_main_joint" type="revolute">
    <parent link="base_link"/>
    <child link="no81_bot_straw"/>
    <origin xyz="0.0368124552685 -0.0929776485888 0"/>
    <axis xyz="-0.0929776485888 -0.0368124552685 0"/>
    <limit effort="300" lower="-1.5707963268" upper="0" velocity="0.1"/>
    <mimic joint="master_main_joint" multiplier="1.0" offset="0.0"/>
    <dynamics damping="50" friction="1"/>
  </joint>
  <joint name="no81_slave_joint" type="revolute">
    <parent link="no81_bot_straw"/>
    <child link="no81_top_straw"/>
    <origin xyz="0 0 0.3"/>
    <axis xyz="-0.0929776485888 -0.0368124552685 0"/>
    <limit effort="300" lower="-3.14159265359" upper="3.14159265359" velocity="0.1"/>
    <mimic joint="no81_main_joint" multiplier="-2.0" offset="0.0"/>
    <dynamics damping="50" friction="1"/>
  </joint>
  <link name="no82_bot_straw">
    <visual>
      <geometry>
        <cylinder length="0.3" radius="0.02"/>
      </geometry>
      <origin rpy="0 0 0" xyz="0 0 0.15"/>
      <material name="green">
        <color rgba="0 1 0 1"/>
      </material>
    </visual>
  </link>
  <link name="no82_top_straw">
    <visual>
      <geometry>
        <cylinder length="0.3" radius="0.02"/>
      </geometry>
      <origin rpy="0 0 0" xyz="0 0 0.15"/>
      <material name="green">
        <color rgba="0 1 0 1"/>
      </material>
    </visual>
  </link>
  <joint name="no82_main_joint" type="revolute">
    <parent link="base_link"/>
    <child link="no82_bot_straw"/>
    <origin xyz="0.0425779291565 -0.0904827052466 0"/>
    <axis xyz="-0.0904827052466 -0.0425779291565 0"/>
    <limit effort="300" lower="-1.5707963268" upper="0" velocity="0.1"/>
    <mimic joint="master_main_joint" multiplier="1.0" offset="0.0"/>
    <dynamics damping="50" friction="1"/>
  </joint>
  <joint name="no82_slave_joint" type="revolute">
    <parent link="no82_bot_straw"/>
    <child link="no82_top_straw"/>
    <origin xyz="0 0 0.3"/>
    <axis xyz="-0.0904827052466 -0.0425779291565 0"/>
    <limit effort="300" lower="-3.14159265359" upper="3.14159265359" velocity="0.1"/>
    <mimic joint="no82_main_joint" multiplier="-2.0" offset="0.0"/>
    <dynamics damping="50" friction="1"/>
  </joint>
  <link name="no83_bot_straw">
    <visual>
      <geometry>
        <cylinder length="0.3" radius="0.02"/>
      </geometry>
      <origin rpy="0 0 0" xyz="0 0 0.15"/>
      <material name="green">
        <color rgba="0 1 0 1"/>
      </material>
    </visual>
  </link>
  <link name="no83_top_straw">
    <visual>
      <geometry>
        <cylinder length="0.3" radius="0.02"/>
      </geometry>
      <origin rpy="0 0 0" xyz="0 0 0.15"/>
      <material name="green">
        <color rgba="0 1 0 1"/>
      </material>
    </visual>
  </link>
  <joint name="no83_main_joint" type="revolute">
    <parent link="base_link"/>
    <child link="no83_bot_straw"/>
    <origin xyz="0.0481753674102 -0.0876306680044 0"/>
    <axis xyz="-0.0876306680044 -0.0481753674102 0"/>
    <limit effort="300" lower="-1.5707963268" upper="0" velocity="0.1"/>
    <mimic joint="master_main_joint" multiplier="1.0" offset="0.0"/>
    <dynamics damping="50" friction="1"/>
  </joint>
  <joint name="no83_slave_joint" type="revolute">
    <parent link="no83_bot_straw"/>
    <child link="no83_top_straw"/>
    <origin xyz="0 0 0.3"/>
    <axis xyz="-0.0876306680044 -0.0481753674102 0"/>
    <limit effort="300" lower="-3.14159265359" upper="3.14159265359" velocity="0.1"/>
    <mimic joint="no83_main_joint" multiplier="-2.0" offset="0.0"/>
    <dynamics damping="50" friction="1"/>
  </joint>
  <link name="no84_bot_straw">
    <visual>
      <geometry>
        <cylinder length="0.3" radius="0.02"/>
      </geometry>
      <origin rpy="0 0 0" xyz="0 0 0.15"/>
      <material name="green">
        <color rgba="0 1 0 1"/>
      </material>
    </visual>
  </link>
  <link name="no84_top_straw">
    <visual>
      <geometry>
        <cylinder length="0.3" radius="0.02"/>
      </geometry>
      <origin rpy="0 0 0" xyz="0 0 0.15"/>
      <material name="green">
        <color rgba="0 1 0 1"/>
      </material>
    </visual>
  </link>
  <joint name="no84_main_joint" type="revolute">
    <parent link="base_link"/>
    <child link="no84_bot_straw"/>
    <origin xyz="0.0535826794979 -0.0844327925502 0"/>
    <axis xyz="-0.0844327925502 -0.0535826794979 0"/>
    <limit effort="300" lower="-1.5707963268" upper="0" velocity="0.1"/>
    <mimic joint="master_main_joint" multiplier="1.0" offset="0.0"/>
    <dynamics damping="50" friction="1"/>
  </joint>
  <joint name="no84_slave_joint" type="revolute">
    <parent link="no84_bot_straw"/>
    <child link="no84_top_straw"/>
    <origin xyz="0 0 0.3"/>
    <axis xyz="-0.0844327925502 -0.0535826794979 0"/>
    <limit effort="300" lower="-3.14159265359" upper="3.14159265359" velocity="0.1"/>
    <mimic joint="no84_main_joint" multiplier="-2.0" offset="0.0"/>
    <dynamics damping="50" friction="1"/>
  </joint>
  <link name="no85_bot_straw">
    <visual>
      <geometry>
        <cylinder length="0.3" radius="0.02"/>
      </geometry>
      <origin rpy="0 0 0" xyz="0 0 0.15"/>
      <material name="green">
        <color rgba="0 1 0 1"/>
      </material>
    </visual>
  </link>
  <link name="no85_top_straw">
    <visual>
      <geometry>
        <cylinder length="0.3" radius="0.02"/>
      </geometry>
      <origin rpy="0 0 0" xyz="0 0 0.15"/>
      <material name="green">
        <color rgba="0 1 0 1"/>
      </material>
    </visual>
  </link>
  <joint name="no85_main_joint" type="revolute">
    <parent link="base_link"/>
    <child link="no85_bot_straw"/>
    <origin xyz="0.0587785252293 -0.0809016994375 0"/>
    <axis xyz="-0.0809016994375 -0.0587785252293 0"/>
    <limit effort="300" lower="-1.5707963268" upper="0" velocity="0.1"/>
    <mimic joint="master_main_joint" multiplier="1.0" offset="0.0"/>
    <dynamics damping="50" friction="1"/>
  </joint>
  <joint name="no85_slave_joint" type="revolute">
    <parent link="no85_bot_straw"/>
    <child link="no85_top_straw"/>
    <origin xyz="0 0 0.3"/>
    <axis xyz="-0.0809016994375 -0.0587785252293 0"/>
    <limit effort="300" lower="-3.14159265359" upper="3.14159265359" velocity="0.1"/>
    <mimic joint="no85_main_joint" multiplier="-2.0" offset="0.0"/>
    <dynamics damping="50" friction="1"/>
  </joint>
  <link name="no86_bot_straw">
    <visual>
      <geometry>
        <cylinder length="0.3" radius="0.02"/>
      </geometry>
      <origin rpy="0 0 0" xyz="0 0 0.15"/>
      <material name="green">
        <color rgba="0 1 0 1"/>
      </material>
    </visual>
  </link>
  <link name="no86_top_straw">
    <visual>
      <geometry>
        <cylinder length="0.3" radius="0.02"/>
      </geometry>
      <origin rpy="0 0 0" xyz="0 0 0.15"/>
      <material name="green">
        <color rgba="0 1 0 1"/>
      </material>
    </visual>
  </link>
  <joint name="no86_main_joint" type="revolute">
    <parent link="base_link"/>
    <child link="no86_bot_straw"/>
    <origin xyz="0.0637423989749 -0.0770513242776 0"/>
    <axis xyz="-0.0770513242776 -0.0637423989749 0"/>
    <limit effort="300" lower="-1.5707963268" upper="0" velocity="0.1"/>
    <mimic joint="master_main_joint" multiplier="1.0" offset="0.0"/>
    <dynamics damping="50" friction="1"/>
  </joint>
  <joint name="no86_slave_joint" type="revolute">
    <parent link="no86_bot_straw"/>
    <child link="no86_top_straw"/>
    <origin xyz="0 0 0.3"/>
    <axis xyz="-0.0770513242776 -0.0637423989749 0"/>
    <limit effort="300" lower="-3.14159265359" upper="3.14159265359" velocity="0.1"/>
    <mimic joint="no86_main_joint" multiplier="-2.0" offset="0.0"/>
    <dynamics damping="50" friction="1"/>
  </joint>
  <link name="no87_bot_straw">
    <visual>
      <geometry>
        <cylinder length="0.3" radius="0.02"/>
      </geometry>
      <origin rpy="0 0 0" xyz="0 0 0.15"/>
      <material name="green">
        <color rgba="0 1 0 1"/>
      </material>
    </visual>
  </link>
  <link name="no87_top_straw">
    <visual>
      <geometry>
        <cylinder length="0.3" radius="0.02"/>
      </geometry>
      <origin rpy="0 0 0" xyz="0 0 0.15"/>
      <material name="green">
        <color rgba="0 1 0 1"/>
      </material>
    </visual>
  </link>
  <joint name="no87_main_joint" type="revolute">
    <parent link="base_link"/>
    <child link="no87_bot_straw"/>
    <origin xyz="0.0684547105929 -0.0728968627421 0"/>
    <axis xyz="-0.0728968627421 -0.0684547105929 0"/>
    <limit effort="300" lower="-1.5707963268" upper="0" velocity="0.1"/>
    <mimic joint="master_main_joint" multiplier="1.0" offset="0.0"/>
    <dynamics damping="50" friction="1"/>
  </joint>
  <joint name="no87_slave_joint" type="revolute">
    <parent link="no87_bot_straw"/>
    <child link="no87_top_straw"/>
    <origin xyz="0 0 0.3"/>
    <axis xyz="-0.0728968627421 -0.0684547105929 0"/>
    <limit effort="300" lower="-3.14159265359" upper="3.14159265359" velocity="0.1"/>
    <mimic joint="no87_main_joint" multiplier="-2.0" offset="0.0"/>
    <dynamics damping="50" friction="1"/>
  </joint>
  <link name="no88_bot_straw">
    <visual>
      <geometry>
        <cylinder length="0.3" radius="0.02"/>
      </geometry>
      <origin rpy="0 0 0" xyz="0 0 0.15"/>
      <material name="green">
        <color rgba="0 1 0 1"/>
      </material>
    </visual>
  </link>
  <link name="no88_top_straw">
    <visual>
      <geometry>
        <cylinder length="0.3" radius="0.02"/>
      </geometry>
      <origin rpy="0 0 0" xyz="0 0 0.15"/>
      <material name="green">
        <color rgba="0 1 0 1"/>
      </material>
    </visual>
  </link>
  <joint name="no88_main_joint" type="revolute">
    <parent link="base_link"/>
    <child link="no88_bot_straw"/>
    <origin xyz="0.0728968627422 -0.0684547105928 0"/>
    <axis xyz="-0.0684547105928 -0.0728968627422 0"/>
    <limit effort="300" lower="-1.5707963268" upper="0" velocity="0.1"/>
    <mimic joint="master_main_joint" multiplier="1.0" offset="0.0"/>
    <dynamics damping="50" friction="1"/>
  </joint>
  <joint name="no88_slave_joint" type="revolute">
    <parent link="no88_bot_straw"/>
    <child link="no88_top_straw"/>
    <origin xyz="0 0 0.3"/>
    <axis xyz="-0.0684547105928 -0.0728968627422 0"/>
    <limit effort="300" lower="-3.14159265359" upper="3.14159265359" velocity="0.1"/>
    <mimic joint="no88_main_joint" multiplier="-2.0" offset="0.0"/>
    <dynamics damping="50" friction="1"/>
  </joint>
  <link name="no89_bot_straw">
    <visual>
      <geometry>
        <cylinder length="0.3" radius="0.02"/>
      </geometry>
      <origin rpy="0 0 0" xyz="0 0 0.15"/>
      <material name="green">
        <color rgba="0 1 0 1"/>
      </material>
    </visual>
  </link>
  <link name="no89_top_straw">
    <visual>
      <geometry>
        <cylinder length="0.3" radius="0.02"/>
      </geometry>
      <origin rpy="0 0 0" xyz="0 0 0.15"/>
      <material name="green">
        <color rgba="0 1 0 1"/>
      </material>
    </visual>
  </link>
  <joint name="no89_main_joint" type="revolute">
    <parent link="base_link"/>
    <child link="no89_bot_straw"/>
    <origin xyz="0.0770513242776 -0.0637423989748 0"/>
    <axis xyz="-0.0637423989748 -0.0770513242776 0"/>
    <limit effort="300" lower="-1.5707963268" upper="0" velocity="0.1"/>
    <mimic joint="master_main_joint" multiplier="1.0" offset="0.0"/>
    <dynamics damping="50" friction="1"/>
  </joint>
  <joint name="no89_slave_joint" type="revolute">
    <parent link="no89_bot_straw"/>
    <child link="no89_top_straw"/>
    <origin xyz="0 0 0.3"/>
    <axis xyz="-0.0637423989748 -0.0770513242776 0"/>
    <limit effort="300" lower="-3.14159265359" upper="3.14159265359" velocity="0.1"/>
    <mimic joint="no89_main_joint" multiplier="-2.0" offset="0.0"/>
    <dynamics damping="50" friction="1"/>
  </joint>
  <link name="no90_bot_straw">
    <visual>
      <geometry>
        <cylinder length="0.3" radius="0.02"/>
      </geometry>
      <origin rpy="0 0 0" xyz="0 0 0.15"/>
      <material name="green">
        <color rgba="0 1 0 1"/>
      </material>
    </visual>
  </link>
  <link name="no90_top_straw">
    <visual>
      <geometry>
        <cylinder length="0.3" radius="0.02"/>
      </geometry>
      <origin rpy="0 0 0" xyz="0 0 0.15"/>
      <material name="green">
        <color rgba="0 1 0 1"/>
      </material>
    </visual>
  </link>
  <joint name="no90_main_joint" type="revolute">
    <parent link="base_link"/>
    <child link="no90_bot_straw"/>
    <origin xyz="0.0809016994375 -0.0587785252292 0"/>
    <axis xyz="-0.0587785252292 -0.0809016994375 0"/>
    <limit effort="300" lower="-1.5707963268" upper="0" velocity="0.1"/>
    <mimic joint="master_main_joint" multiplier="1.0" offset="0.0"/>
    <dynamics damping="50" friction="1"/>
  </joint>
  <joint name="no90_slave_joint" type="revolute">
    <parent link="no90_bot_straw"/>
    <child link="no90_top_straw"/>
    <origin xyz="0 0 0.3"/>
    <axis xyz="-0.0587785252292 -0.0809016994375 0"/>
    <limit effort="300" lower="-3.14159265359" upper="3.14159265359" velocity="0.1"/>
    <mimic joint="no90_main_joint" multiplier="-2.0" offset="0.0"/>
    <dynamics damping="50" friction="1"/>
  </joint>
  <link name="no91_bot_straw">
    <visual>
      <geometry>
        <cylinder length="0.3" radius="0.02"/>
      </geometry>
      <origin rpy="0 0 0" xyz="0 0 0.15"/>
      <material name="green">
        <color rgba="0 1 0 1"/>
      </material>
    </visual>
  </link>
  <link name="no91_top_straw">
    <visual>
      <geometry>
        <cylinder length="0.3" radius="0.02"/>
      </geometry>
      <origin rpy="0 0 0" xyz="0 0 0.15"/>
      <material name="green">
        <color rgba="0 1 0 1"/>
      </material>
    </visual>
  </link>
  <joint name="no91_main_joint" type="revolute">
    <parent link="base_link"/>
    <child link="no91_bot_straw"/>
    <origin xyz="0.0844327925502 -0.0535826794979 0"/>
    <axis xyz="-0.0535826794979 -0.0844327925502 0"/>
    <limit effort="300" lower="-1.5707963268" upper="0" velocity="0.1"/>
    <mimic joint="master_main_joint" multiplier="1.0" offset="0.0"/>
    <dynamics damping="50" friction="1"/>
  </joint>
  <joint name="no91_slave_joint" type="revolute">
    <parent link="no91_bot_straw"/>
    <child link="no91_top_straw"/>
    <origin xyz="0 0 0.3"/>
    <axis xyz="-0.0535826794979 -0.0844327925502 0"/>
    <limit effort="300" lower="-3.14159265359" upper="3.14159265359" velocity="0.1"/>
    <mimic joint="no91_main_joint" multiplier="-2.0" offset="0.0"/>
    <dynamics damping="50" friction="1"/>
  </joint>
  <link name="no92_bot_straw">
    <visual>
      <geometry>
        <cylinder length="0.3" radius="0.02"/>
      </geometry>
      <origin rpy="0 0 0" xyz="0 0 0.15"/>
      <material name="green">
        <color rgba="0 1 0 1"/>
      </material>
    </visual>
  </link>
  <link name="no92_top_straw">
    <visual>
      <geometry>
        <cylinder length="0.3" radius="0.02"/>
      </geometry>
      <origin rpy="0 0 0" xyz="0 0 0.15"/>
      <material name="green">
        <color rgba="0 1 0 1"/>
      </material>
    </visual>
  </link>
  <joint name="no92_main_joint" type="revolute">
    <parent link="base_link"/>
    <child link="no92_bot_straw"/>
    <origin xyz="0.0876306680044 -0.0481753674101 0"/>
    <axis xyz="-0.0481753674101 -0.0876306680044 0"/>
    <limit effort="300" lower="-1.5707963268" upper="0" velocity="0.1"/>
    <mimic joint="master_main_joint" multiplier="1.0" offset="0.0"/>
    <dynamics damping="50" friction="1"/>
  </joint>
  <joint name="no92_slave_joint" type="revolute">
    <parent link="no92_bot_straw"/>
    <child link="no92_top_straw"/>
    <origin xyz="0 0 0.3"/>
    <axis xyz="-0.0481753674101 -0.0876306680044 0"/>
    <limit effort="300" lower="-3.14159265359" upper="3.14159265359" velocity="0.1"/>
    <mimic joint="no92_main_joint" multiplier="-2.0" offset="0.0"/>
    <dynamics damping="50" friction="1"/>
  </joint>
  <link name="no93_bot_straw">
    <visual>
      <geometry>
        <cylinder length="0.3" radius="0.02"/>
      </geometry>
      <origin rpy="0 0 0" xyz="0 0 0.15"/>
      <material name="green">
        <color rgba="0 1 0 1"/>
      </material>
    </visual>
  </link>
  <link name="no93_top_straw">
    <visual>
      <geometry>
        <cylinder length="0.3" radius="0.02"/>
      </geometry>
      <origin rpy="0 0 0" xyz="0 0 0.15"/>
      <material name="green">
        <color rgba="0 1 0 1"/>
      </material>
    </visual>
  </link>
  <joint name="no93_main_joint" type="revolute">
    <parent link="base_link"/>
    <child link="no93_bot_straw"/>
    <origin xyz="0.0904827052466 -0.0425779291565 0"/>
    <axis xyz="-0.0425779291565 -0.0904827052466 0"/>
    <limit effort="300" lower="-1.5707963268" upper="0" velocity="0.1"/>
    <mimic joint="master_main_joint" multiplier="1.0" offset="0.0"/>
    <dynamics damping="50" friction="1"/>
  </joint>
  <joint name="no93_slave_joint" type="revolute">
    <parent link="no93_bot_straw"/>
    <child link="no93_top_straw"/>
    <origin xyz="0 0 0.3"/>
    <axis xyz="-0.0425779291565 -0.0904827052466 0"/>
    <limit effort="300" lower="-3.14159265359" upper="3.14159265359" velocity="0.1"/>
    <mimic joint="no93_main_joint" multiplier="-2.0" offset="0.0"/>
    <dynamics damping="50" friction="1"/>
  </joint>
  <link name="no94_bot_straw">
    <visual>
      <geometry>
        <cylinder length="0.3" radius="0.02"/>
      </geometry>
      <origin rpy="0 0 0" xyz="0 0 0.15"/>
      <material name="green">
        <color rgba="0 1 0 1"/>
      </material>
    </visual>
  </link>
  <link name="no94_top_straw">
    <visual>
      <geometry>
        <cylinder length="0.3" radius="0.02"/>
      </geometry>
      <origin rpy="0 0 0" xyz="0 0 0.15"/>
      <material name="green">
        <color rgba="0 1 0 1"/>
      </material>
    </visual>
  </link>
  <joint name="no94_main_joint" type="revolute">
    <parent link="base_link"/>
    <child link="no94_bot_straw"/>
    <origin xyz="0.0929776485888 -0.0368124552684 0"/>
    <axis xyz="-0.0368124552684 -0.0929776485888 0"/>
    <limit effort="300" lower="-1.5707963268" upper="0" velocity="0.1"/>
    <mimic joint="master_main_joint" multiplier="1.0" offset="0.0"/>
    <dynamics damping="50" friction="1"/>
  </joint>
  <joint name="no94_slave_joint" type="revolute">
    <parent link="no94_bot_straw"/>
    <child link="no94_top_straw"/>
    <origin xyz="0 0 0.3"/>
    <axis xyz="-0.0368124552684 -0.0929776485888 0"/>
    <limit effort="300" lower="-3.14159265359" upper="3.14159265359" velocity="0.1"/>
    <mimic joint="no94_main_joint" multiplier="-2.0" offset="0.0"/>
    <dynamics damping="50" friction="1"/>
  </joint>
  <link name="no95_bot_straw">
    <visual>
      <geometry>
        <cylinder length="0.3" radius="0.02"/>
      </geometry>
      <origin rpy="0 0 0" xyz="0 0 0.15"/>
      <material name="green">
        <color rgba="0 1 0 1"/>
      </material>
    </visual>
  </link>
  <link name="no95_top_straw">
    <visual>
      <geometry>
        <cylinder length="0.3" radius="0.02"/>
      </geometry>
      <origin rpy="0 0 0" xyz="0 0 0.15"/>
      <material name="green">
        <color rgba="0 1 0 1"/>
      </material>
    </visual>
  </link>
  <joint name="no95_main_joint" type="revolute">
    <parent link="base_link"/>
    <child link="no95_bot_straw"/>
    <origin xyz="0.0951056516295 -0.0309016994375 0"/>
    <axis xyz="-0.0309016994375 -0.0951056516295 0"/>
    <limit effort="300" lower="-1.5707963268" upper="0" velocity="0.1"/>
    <mimic joint="master_main_joint" multiplier="1.0" offset="0.0"/>
    <dynamics damping="50" friction="1"/>
  </joint>
  <joint name="no95_slave_joint" type="revolute">
    <parent link="no95_bot_straw"/>
    <child link="no95_top_straw"/>
    <origin xyz="0 0 0.3"/>
    <axis xyz="-0.0309016994375 -0.0951056516295 0"/>
    <limit effort="300" lower="-3.14159265359" upper="3.14159265359" velocity="0.1"/>
    <mimic joint="no95_main_joint" multiplier="-2.0" offset="0.0"/>
    <dynamics damping="50" friction="1"/>
  </joint>
  <link name="no96_bot_straw">
    <visual>
      <geometry>
        <cylinder length="0.3" radius="0.02"/>
      </geometry>
      <origin rpy="0 0 0" xyz="0 0 0.15"/>
      <material name="green">
        <color rgba="0 1 0 1"/>
      </material>
    </visual>
  </link>
  <link name="no96_top_straw">
    <visual>
      <geometry>
        <cylinder length="0.3" radius="0.02"/>
      </geometry>
      <origin rpy="0 0 0" xyz="0 0 0.15"/>
      <material name="green">
        <color rgba="0 1 0 1"/>
      </material>
    </visual>
  </link>
  <joint name="no96_main_joint" type="revolute">
    <parent link="base_link"/>
    <child link="no96_bot_straw"/>
    <origin xyz="0.0968583161129 -0.0248689887164 0"/>
    <axis xyz="-0.0248689887164 -0.0968583161129 0"/>
    <limit effort="300" lower="-1.5707963268" upper="0" velocity="0.1"/>
    <mimic joint="master_main_joint" multiplier="1.0" offset="0.0"/>
    <dynamics damping="50" friction="1"/>
  </joint>
  <joint name="no96_slave_joint" type="revolute">
    <parent link="no96_bot_straw"/>
    <child link="no96_top_straw"/>
    <origin xyz="0 0 0.3"/>
    <axis xyz="-0.0248689887164 -0.0968583161129 0"/>
    <limit effort="300" lower="-3.14159265359" upper="3.14159265359" velocity="0.1"/>
    <mimic joint="no96_main_joint" multiplier="-2.0" offset="0.0"/>
    <dynamics damping="50" friction="1"/>
  </joint>
  <link name="no97_bot_straw">
    <visual>
      <geometry>
        <cylinder length="0.3" radius="0.02"/>
      </geometry>
      <origin rpy="0 0 0" xyz="0 0 0.15"/>
      <material name="green">
        <color rgba="0 1 0 1"/>
      </material>
    </visual>
  </link>
  <link name="no97_top_straw">
    <visual>
      <geometry>
        <cylinder length="0.3" radius="0.02"/>
      </geometry>
      <origin rpy="0 0 0" xyz="0 0 0.15"/>
      <material name="green">
        <color rgba="0 1 0 1"/>
      </material>
    </visual>
  </link>
  <joint name="no97_main_joint" type="revolute">
    <parent link="base_link"/>
    <child link="no97_bot_straw"/>
    <origin xyz="0.0982287250729 -0.0187381314585 0"/>
    <axis xyz="-0.0187381314585 -0.0982287250729 0"/>
    <limit effort="300" lower="-1.5707963268" upper="0" velocity="0.1"/>
    <mimic joint="master_main_joint" multiplier="1.0" offset="0.0"/>
    <dynamics damping="50" friction="1"/>
  </joint>
  <joint name="no97_slave_joint" type="revolute">
    <parent link="no97_bot_straw"/>
    <child link="no97_top_straw"/>
    <origin xyz="0 0 0.3"/>
    <axis xyz="-0.0187381314585 -0.0982287250729 0"/>
    <limit effort="300" lower="-3.14159265359" upper="3.14159265359" velocity="0.1"/>
    <mimic joint="no97_main_joint" multiplier="-2.0" offset="0.0"/>
    <dynamics damping="50" friction="1"/>
  </joint>
  <link name="no98_bot_straw">
    <visual>
      <geometry>
        <cylinder length="0.3" radius="0.02"/>
      </geometry>
      <origin rpy="0 0 0" xyz="0 0 0.15"/>
      <material name="green">
        <color rgba="0 1 0 1"/>
      </material>
    </visual>
  </link>
  <link name="no98_top_straw">
    <visual>
      <geometry>
        <cylinder length="0.3" radius="0.02"/>
      </geometry>
      <origin rpy="0 0 0" xyz="0 0 0.15"/>
      <material name="green">
        <color rgba="0 1 0 1"/>
      </material>
    </visual>
  </link>
  <joint name="no98_main_joint" type="revolute">
    <parent link="base_link"/>
    <child link="no98_bot_straw"/>
    <origin xyz="0.0992114701315 -0.0125333233564 0"/>
    <axis xyz="-0.0125333233564 -0.0992114701315 0"/>
    <limit effort="300" lower="-1.5707963268" upper="0" velocity="0.1"/>
    <mimic joint="master_main_joint" multiplier="1.0" offset="0.0"/>
    <dynamics damping="50" friction="1"/>
  </joint>
  <joint name="no98_slave_joint" type="revolute">
    <parent link="no98_bot_straw"/>
    <child link="no98_top_straw"/>
    <origin xyz="0 0 0.3"/>
    <axis xyz="-0.0125333233564 -0.0992114701315 0"/>
    <limit effort="300" lower="-3.14159265359" upper="3.14159265359" velocity="0.1"/>
    <mimic joint="no98_main_joint" multiplier="-2.0" offset="0.0"/>
    <dynamics damping="50" friction="1"/>
  </joint>
  <link name="no99_bot_straw">
    <visual>
      <geometry>
        <cylinder length="0.3" radius="0.02"/>
      </geometry>
      <origin rpy="0 0 0" xyz="0 0 0.15"/>
      <material name="green">
        <color rgba="0 1 0 1"/>
      </material>
    </visual>
  </link>
  <link name="no99_top_straw">
    <visual>
      <geometry>
        <cylinder length="0.3" radius="0.02"/>
      </geometry>
      <origin rpy="0 0 0" xyz="0 0 0.15"/>
      <material name="green">
        <color rgba="0 1 0 1"/>
      </material>
    </visual>
  </link>
  <joint name="no99_main_joint" type="revolute">
    <parent link="base_link"/>
    <child link="no99_bot_straw"/>
    <origin xyz="0.0998026728428 -0.00627905195289 0"/>
    <axis xyz="-0.00627905195289 -0.0998026728428 0"/>
    <limit effort="300" lower="-1.5707963268" upper="0" velocity="0.1"/>
    <mimic joint="master_main_joint" multiplier="1.0" offset="0.0"/>
    <dynamics damping="50" friction="1"/>
  </joint>
  <joint name="no99_slave_joint" type="revolute">
    <parent link="no99_bot_straw"/>
    <child link="no99_top_straw"/>
    <origin xyz="0 0 0.3"/>
    <axis xyz="-0.00627905195289 -0.0998026728428 0"/>
    <limit effort="300" lower="-3.14159265359" upper="3.14159265359" velocity="0.1"/>
    <mimic joint="no99_main_joint" multiplier="-2.0" offset="0.0"/>
    <dynamics damping="50" friction="1"/>
  </joint>
</robot>

