<?xml version="1.0" ?>
<!-- =================================================================================== -->
<!-- |    This document was autogenerated by xacro from grip.xacro                     | -->
<!-- |    EDITING THIS FILE BY HAND IS NOT RECOMMENDED                                 | -->
<!-- =================================================================================== -->
<robot name="test_bot" xmlns:xacro="http://www.ros.org/wiki/xacro">
  <link name="base_footprint">
    <visual>
      <geometry>
        <cylinder length="0.02" radius="1"/>
      </geometry>
      <origin rpy="0 0 0"/>
      <material name="red">
        <color rgba="1 0 0 1"/>
      </material>
    </visual>
  </link>
  <joint name="base_footprint_joint" type="revolute">
    <child name="base_link"/>
    <parent name="base_footprint"/>
    <origin xyz="$0 0 0"/>
    <axis xyz="$0 0 1"/>
    <limit effort="300" lower="-1.5707963268" upper="0" velocity="0.1"/>
    <dynamics damping="50" friction="1"/>
  </joint>
  <link name="base_link">
    <visual>
      <geometry>
        <cylinder length="0.02" radius="1"/>
      </geometry>
      <origin rpy="0 0 0"/>
      <material name="red">
        <color rgba="1 0 0 1"/>
      </material>
    </visual>
  </link>
  <link name="master_bot_straw">
    <visual>
      <geometry>
        <cylinder length="0.3" radius="0.02"/>
      </geometry>
      <origin rpy="0 0 0" xyz="0 0 0.15"/>
      <material name="green">
        <color rgba="0 1 0 1"/>
      </material>
    </visual>
  </link>
  <link name="master_top_straw">
    <visual>
      <geometry>
        <cylinder length="0.3" radius="0.02"/>
      </geometry>
      <origin rpy="0 0 0" xyz="0 0 0.15"/>
      <material name="green">
        <color rgba="0 1 0 1"/>
      </material>
    </visual>
  </link>
  <joint name="master_main_joint" type="revolute">
    <parent link="base_link"/>
    <child link="master_bot_straw"/>
    <origin xyz="0.1 0.0 0.01"/>
    <axis xyz="0.0 -0.1 0"/>
    <limit effort="300" lower="-1.5707963268" upper="0" velocity="0.1"/>
    <dynamics damping="50" friction="1"/>
  </joint>
  <joint name="master_slave_joint" type="revolute">
    <parent link="master_bot_straw"/>
    <child link="master_top_straw"/>
    <origin xyz="0 0 0.3"/>
    <axis xyz="0.0 -0.1 0"/>
    <limit effort="300" lower="-3.14159265359" upper="3.14159265359" velocity="0.1"/>
    <mimic joint="master_main_joint" multiplier="-2.0" offset="0.0"/>
    <dynamics damping="50" friction="1"/>
  </joint>
  <link name="_no_1_bot_straw">
    <visual>
      <geometry>
        <cylinder length="0.3" radius="0.02"/>
      </geometry>
      <origin rpy="0 0 0" xyz="0 0 0.15"/>
      <material name="green">
        <color rgba="0 1 0 1"/>
      </material>
    </visual>
  </link>
  <link name="_no_1_top_straw">
    <visual>
      <geometry>
        <cylinder length="0.3" radius="0.02"/>
      </geometry>
      <origin rpy="0 0 0" xyz="0 0 0.15"/>
      <material name="green">
        <color rgba="0 1 0 1"/>
      </material>
    </visual>
  </link>
  <joint name="_no_1_main_joint" type="revolute">
    <parent link="base_link"/>
    <child link="_no_1_bot_straw"/>
    <origin xyz="0.0809016994375 0.0587785252293 0.01"/>
    <axis xyz="0.0587785252293 -0.0809016994375 0"/>
    <limit effort="300" lower="-1.5707963268" upper="0" velocity="0.1"/>
    <mimic joint="master_main_joint" multiplier="1.0" offset="0.0"/>
    <dynamics damping="50" friction="1"/>
  </joint>
  <joint name="_no_1_slave_joint" type="revolute">
    <parent link="_no_1_bot_straw"/>
    <child link="_no_1_top_straw"/>
    <origin xyz="0 0 0.3"/>
    <axis xyz="0.0587785252293 -0.0809016994375 0"/>
    <limit effort="300" lower="-3.14159265359" upper="3.14159265359" velocity="0.1"/>
    <mimic joint="_no_1_main_joint" multiplier="-2.0" offset="0.0"/>
    <dynamics damping="50" friction="1"/>
  </joint>
  <link name="_no_2_bot_straw">
    <visual>
      <geometry>
        <cylinder length="0.3" radius="0.02"/>
      </geometry>
      <origin rpy="0 0 0" xyz="0 0 0.15"/>
      <material name="green">
        <color rgba="0 1 0 1"/>
      </material>
    </visual>
  </link>
  <link name="_no_2_top_straw">
    <visual>
      <geometry>
        <cylinder length="0.3" radius="0.02"/>
      </geometry>
      <origin rpy="0 0 0" xyz="0 0 0.15"/>
      <material name="green">
        <color rgba="0 1 0 1"/>
      </material>
    </visual>
  </link>
  <joint name="_no_2_main_joint" type="revolute">
    <parent link="base_link"/>
    <child link="_no_2_bot_straw"/>
    <origin xyz="0.0309016994375 0.0951056516295 0.01"/>
    <axis xyz="0.0951056516295 -0.0309016994375 0"/>
    <limit effort="300" lower="-1.5707963268" upper="0" velocity="0.1"/>
    <mimic joint="master_main_joint" multiplier="1.0" offset="0.0"/>
    <dynamics damping="50" friction="1"/>
  </joint>
  <joint name="_no_2_slave_joint" type="revolute">
    <parent link="_no_2_bot_straw"/>
    <child link="_no_2_top_straw"/>
    <origin xyz="0 0 0.3"/>
    <axis xyz="0.0951056516295 -0.0309016994375 0"/>
    <limit effort="300" lower="-3.14159265359" upper="3.14159265359" velocity="0.1"/>
    <mimic joint="_no_2_main_joint" multiplier="-2.0" offset="0.0"/>
    <dynamics damping="50" friction="1"/>
  </joint>
  <link name="_no_3_bot_straw">
    <visual>
      <geometry>
        <cylinder length="0.3" radius="0.02"/>
      </geometry>
      <origin rpy="0 0 0" xyz="0 0 0.15"/>
      <material name="green">
        <color rgba="0 1 0 1"/>
      </material>
    </visual>
  </link>
  <link name="_no_3_top_straw">
    <visual>
      <geometry>
        <cylinder length="0.3" radius="0.02"/>
      </geometry>
      <origin rpy="0 0 0" xyz="0 0 0.15"/>
      <material name="green">
        <color rgba="0 1 0 1"/>
      </material>
    </visual>
  </link>
  <joint name="_no_3_main_joint" type="revolute">
    <parent link="base_link"/>
    <child link="_no_3_bot_straw"/>
    <origin xyz="-0.0309016994375 0.0951056516295 0.01"/>
    <axis xyz="0.0951056516295 0.0309016994375 0"/>
    <limit effort="300" lower="-1.5707963268" upper="0" velocity="0.1"/>
    <mimic joint="master_main_joint" multiplier="1.0" offset="0.0"/>
    <dynamics damping="50" friction="1"/>
  </joint>
  <joint name="_no_3_slave_joint" type="revolute">
    <parent link="_no_3_bot_straw"/>
    <child link="_no_3_top_straw"/>
    <origin xyz="0 0 0.3"/>
    <axis xyz="0.0951056516295 0.0309016994375 0"/>
    <limit effort="300" lower="-3.14159265359" upper="3.14159265359" velocity="0.1"/>
    <mimic joint="_no_3_main_joint" multiplier="-2.0" offset="0.0"/>
    <dynamics damping="50" friction="1"/>
  </joint>
  <link name="_no_4_bot_straw">
    <visual>
      <geometry>
        <cylinder length="0.3" radius="0.02"/>
      </geometry>
      <origin rpy="0 0 0" xyz="0 0 0.15"/>
      <material name="green">
        <color rgba="0 1 0 1"/>
      </material>
    </visual>
  </link>
  <link name="_no_4_top_straw">
    <visual>
      <geometry>
        <cylinder length="0.3" radius="0.02"/>
      </geometry>
      <origin rpy="0 0 0" xyz="0 0 0.15"/>
      <material name="green">
        <color rgba="0 1 0 1"/>
      </material>
    </visual>
  </link>
  <joint name="_no_4_main_joint" type="revolute">
    <parent link="base_link"/>
    <child link="_no_4_bot_straw"/>
    <origin xyz="-0.0809016994375 0.0587785252292 0.01"/>
    <axis xyz="0.0587785252292 0.0809016994375 0"/>
    <limit effort="300" lower="-1.5707963268" upper="0" velocity="0.1"/>
    <mimic joint="master_main_joint" multiplier="1.0" offset="0.0"/>
    <dynamics damping="50" friction="1"/>
  </joint>
  <joint name="_no_4_slave_joint" type="revolute">
    <parent link="_no_4_bot_straw"/>
    <child link="_no_4_top_straw"/>
    <origin xyz="0 0 0.3"/>
    <axis xyz="0.0587785252292 0.0809016994375 0"/>
    <limit effort="300" lower="-3.14159265359" upper="3.14159265359" velocity="0.1"/>
    <mimic joint="_no_4_main_joint" multiplier="-2.0" offset="0.0"/>
    <dynamics damping="50" friction="1"/>
  </joint>
  <link name="_no_5_bot_straw">
    <visual>
      <geometry>
        <cylinder length="0.3" radius="0.02"/>
      </geometry>
      <origin rpy="0 0 0" xyz="0 0 0.15"/>
      <material name="green">
        <color rgba="0 1 0 1"/>
      </material>
    </visual>
  </link>
  <link name="_no_5_top_straw">
    <visual>
      <geometry>
        <cylinder length="0.3" radius="0.02"/>
      </geometry>
      <origin rpy="0 0 0" xyz="0 0 0.15"/>
      <material name="green">
        <color rgba="0 1 0 1"/>
      </material>
    </visual>
  </link>
  <joint name="_no_5_main_joint" type="revolute">
    <parent link="base_link"/>
    <child link="_no_5_bot_straw"/>
    <origin xyz="-0.1 -2.0682310711e-14 0.01"/>
    <axis xyz="-2.0682310711e-14 0.1 0"/>
    <limit effort="300" lower="-1.5707963268" upper="0" velocity="0.1"/>
    <mimic joint="master_main_joint" multiplier="1.0" offset="0.0"/>
    <dynamics damping="50" friction="1"/>
  </joint>
  <joint name="_no_5_slave_joint" type="revolute">
    <parent link="_no_5_bot_straw"/>
    <child link="_no_5_top_straw"/>
    <origin xyz="0 0 0.3"/>
    <axis xyz="-2.0682310711e-14 0.1 0"/>
    <limit effort="300" lower="-3.14159265359" upper="3.14159265359" velocity="0.1"/>
    <mimic joint="_no_5_main_joint" multiplier="-2.0" offset="0.0"/>
    <dynamics damping="50" friction="1"/>
  </joint>
  <link name="_no_6_bot_straw">
    <visual>
      <geometry>
        <cylinder length="0.3" radius="0.02"/>
      </geometry>
      <origin rpy="0 0 0" xyz="0 0 0.15"/>
      <material name="green">
        <color rgba="0 1 0 1"/>
      </material>
    </visual>
  </link>
  <link name="_no_6_top_straw">
    <visual>
      <geometry>
        <cylinder length="0.3" radius="0.02"/>
      </geometry>
      <origin rpy="0 0 0" xyz="0 0 0.15"/>
      <material name="green">
        <color rgba="0 1 0 1"/>
      </material>
    </visual>
  </link>
  <joint name="_no_6_main_joint" type="revolute">
    <parent link="base_link"/>
    <child link="_no_6_bot_straw"/>
    <origin xyz="-0.0809016994375 -0.0587785252293 0.01"/>
    <axis xyz="-0.0587785252293 0.0809016994375 0"/>
    <limit effort="300" lower="-1.5707963268" upper="0" velocity="0.1"/>
    <mimic joint="master_main_joint" multiplier="1.0" offset="0.0"/>
    <dynamics damping="50" friction="1"/>
  </joint>
  <joint name="_no_6_slave_joint" type="revolute">
    <parent link="_no_6_bot_straw"/>
    <child link="_no_6_top_straw"/>
    <origin xyz="0 0 0.3"/>
    <axis xyz="-0.0587785252293 0.0809016994375 0"/>
    <limit effort="300" lower="-3.14159265359" upper="3.14159265359" velocity="0.1"/>
    <mimic joint="_no_6_main_joint" multiplier="-2.0" offset="0.0"/>
    <dynamics damping="50" friction="1"/>
  </joint>
  <link name="_no_7_bot_straw">
    <visual>
      <geometry>
        <cylinder length="0.3" radius="0.02"/>
      </geometry>
      <origin rpy="0 0 0" xyz="0 0 0.15"/>
      <material name="green">
        <color rgba="0 1 0 1"/>
      </material>
    </visual>
  </link>
  <link name="_no_7_top_straw">
    <visual>
      <geometry>
        <cylinder length="0.3" radius="0.02"/>
      </geometry>
      <origin rpy="0 0 0" xyz="0 0 0.15"/>
      <material name="green">
        <color rgba="0 1 0 1"/>
      </material>
    </visual>
  </link>
  <joint name="_no_7_main_joint" type="revolute">
    <parent link="base_link"/>
    <child link="_no_7_bot_straw"/>
    <origin xyz="-0.0309016994375 -0.0951056516295 0.01"/>
    <axis xyz="-0.0951056516295 0.0309016994375 0"/>
    <limit effort="300" lower="-1.5707963268" upper="0" velocity="0.1"/>
    <mimic joint="master_main_joint" multiplier="1.0" offset="0.0"/>
    <dynamics damping="50" friction="1"/>
  </joint>
  <joint name="_no_7_slave_joint" type="revolute">
    <parent link="_no_7_bot_straw"/>
    <child link="_no_7_top_straw"/>
    <origin xyz="0 0 0.3"/>
    <axis xyz="-0.0951056516295 0.0309016994375 0"/>
    <limit effort="300" lower="-3.14159265359" upper="3.14159265359" velocity="0.1"/>
    <mimic joint="_no_7_main_joint" multiplier="-2.0" offset="0.0"/>
    <dynamics damping="50" friction="1"/>
  </joint>
  <link name="_no_8_bot_straw">
    <visual>
      <geometry>
        <cylinder length="0.3" radius="0.02"/>
      </geometry>
      <origin rpy="0 0 0" xyz="0 0 0.15"/>
      <material name="green">
        <color rgba="0 1 0 1"/>
      </material>
    </visual>
  </link>
  <link name="_no_8_top_straw">
    <visual>
      <geometry>
        <cylinder length="0.3" radius="0.02"/>
      </geometry>
      <origin rpy="0 0 0" xyz="0 0 0.15"/>
      <material name="green">
        <color rgba="0 1 0 1"/>
      </material>
    </visual>
  </link>
  <joint name="_no_8_main_joint" type="revolute">
    <parent link="base_link"/>
    <child link="_no_8_bot_straw"/>
    <origin xyz="0.0309016994375 -0.0951056516295 0.01"/>
    <axis xyz="-0.0951056516295 -0.0309016994375 0"/>
    <limit effort="300" lower="-1.5707963268" upper="0" velocity="0.1"/>
    <mimic joint="master_main_joint" multiplier="1.0" offset="0.0"/>
    <dynamics damping="50" friction="1"/>
  </joint>
  <joint name="_no_8_slave_joint" type="revolute">
    <parent link="_no_8_bot_straw"/>
    <child link="_no_8_top_straw"/>
    <origin xyz="0 0 0.3"/>
    <axis xyz="-0.0951056516295 -0.0309016994375 0"/>
    <limit effort="300" lower="-3.14159265359" upper="3.14159265359" velocity="0.1"/>
    <mimic joint="_no_8_main_joint" multiplier="-2.0" offset="0.0"/>
    <dynamics damping="50" friction="1"/>
  </joint>
  <link name="_no_9_bot_straw">
    <visual>
      <geometry>
        <cylinder length="0.3" radius="0.02"/>
      </geometry>
      <origin rpy="0 0 0" xyz="0 0 0.15"/>
      <material name="green">
        <color rgba="0 1 0 1"/>
      </material>
    </visual>
  </link>
  <link name="_no_9_top_straw">
    <visual>
      <geometry>
        <cylinder length="0.3" radius="0.02"/>
      </geometry>
      <origin rpy="0 0 0" xyz="0 0 0.15"/>
      <material name="green">
        <color rgba="0 1 0 1"/>
      </material>
    </visual>
  </link>
  <joint name="_no_9_main_joint" type="revolute">
    <parent link="base_link"/>
    <child link="_no_9_bot_straw"/>
    <origin xyz="0.0809016994375 -0.0587785252292 0.01"/>
    <axis xyz="-0.0587785252292 -0.0809016994375 0"/>
    <limit effort="300" lower="-1.5707963268" upper="0" velocity="0.1"/>
    <mimic joint="master_main_joint" multiplier="1.0" offset="0.0"/>
    <dynamics damping="50" friction="1"/>
  </joint>
  <joint name="_no_9_slave_joint" type="revolute">
    <parent link="_no_9_bot_straw"/>
    <child link="_no_9_top_straw"/>
    <origin xyz="0 0 0.3"/>
    <axis xyz="-0.0587785252292 -0.0809016994375 0"/>
    <limit effort="300" lower="-3.14159265359" upper="3.14159265359" velocity="0.1"/>
    <mimic joint="_no_9_main_joint" multiplier="-2.0" offset="0.0"/>
    <dynamics damping="50" friction="1"/>
  </joint>
</robot>

