<?xml version="1.0" ?>
<!-- =================================================================================== -->
<!-- |    This document was autogenerated by xacro from loop.xacro                     | -->
<!-- |    EDITING THIS FILE BY HAND IS NOT RECOMMENDED                                 | -->
<!-- =================================================================================== -->
<robot name="test_bot" xmlns:xacro="http://www.ros.org/wiki/xacro">
  <link name="base_link">
    <visual>
      <geometry>
        <cylinder length="0.3" radius="0.02"/>
      </geometry>
      <origin rpy="$0 {cos(theta)} 0.0" xyz="0 0 0.15"/>
      <material name="green">
        <color rgba="0 1 0 1"/>
      </material>
    </visual>
  </link>
  <link name="no_1">
    <visual>
      <geometry>
        <cylinder length="0.3" radius="0.02"/>
      </geometry>
      <origin rpy="$0 {cos(theta)} 1.0" xyz="0 0 0.15"/>
      <material name="green">
        <color rgba="0 1 0 1"/>
      </material>
    </visual>
  </link>
  <link name="no_2">
    <visual>
      <geometry>
        <cylinder length="0.3" radius="0.02"/>
      </geometry>
      <origin rpy="$0 {cos(theta)} -2.0682310711e-13" xyz="0 0 0.15"/>
      <material name="green">
        <color rgba="0 1 0 1"/>
      </material>
    </visual>
  </link>
  <link name="no_3">
    <visual>
      <geometry>
        <cylinder length="0.3" radius="0.02"/>
      </geometry>
      <origin rpy="$0 {cos(theta)} -1.0" xyz="0 0 0.15"/>
      <material name="green">
        <color rgba="0 1 0 1"/>
      </material>
    </visual>
  </link>
  <joint name="joint1" type="revolute">
    <parent link="base_link"/>
    <child link="no_1"/>
    <origin xyz="0 0 0.3"/>
    <axis xyz="0 0 1"/>
    <limit effort="300" lower="-1.5707963268" upper="0" velocity="0.1"/>
    <dynamics damping="50" friction="1"/>
  </joint>
  <joint name="joint1" type="revolute">
    <parent link="no_1"/>
    <child link="no_2"/>
    <origin xyz="0 0 0.3"/>
    <axis xyz="0 0 1"/>
    <limit effort="300" lower="-1.5707963268" upper="0" velocity="0.1"/>
    <dynamics damping="50" friction="1"/>
  </joint>
  <joint name="joint1" type="revolute">
    <parent link="no_2"/>
    <child link="no_3"/>
    <origin xyz="0 0 0.3"/>
    <axis xyz="0 0 1"/>
    <limit effort="300" lower="-1.5707963268" upper="0" velocity="0.1"/>
    <dynamics damping="50" friction="1"/>
  </joint>
  <joint name="joint1" type="revolute">
    <parent link="no_3"/>
    <child link="base_link"/>
    <origin xyz="0 0 0.3"/>
    <axis xyz="0 0 1"/>
    <limit effort="300" lower="-1.5707963268" upper="0" velocity="0.1"/>
    <dynamics damping="50" friction="1"/>
  </joint>
</robot>

